Workbook

Sheet Main
B2: Founded: 1950 by Morris Ross in Pacifica, California
B3: IPO: 1985 | J3: P | K3: 248.58
B4: CEO: Mr. James G. Conroy | J4: S | K4: =Model!L16 -> 319.45 | L4: Q226
B5: CFO | J5: MC | K5: =K3*K4 -> 79408.881
J6: C | K6: =Model!L48 -> 4288.124 | L6: =L4 -> Q226
J7: D | K7: =Model!L47 -> 1018.512 | L7: =L6 -> Q226
B8: Press | C8: Note | J8: EV | K8: =K5-K6+K7 -> 76139.269
B9: Q226 | C9: 1.4mm shares repurchased at $319mm ~ avg price $228
B10: Q126 | C10: 1.5mm shares repurchased at $319mm ~ avg price $210
B11: Q425 | C11: 1.5mm shares repurchased at $262mm ~ avg price $175
B12: Q325 | C12: 1.7mm shares repurchased at $262mm ~ avg price $154
B13: Q225 | C13: 1.9mm shares repurchased at $262mm ~ avg price $262

Sheet Model
A1: Main
A2: $M | C2: 45416 | D2: 45507 | E2: 45598 | F2: 45689 | G2: 45780 | H2: 45871 | I2: 45962 | J2: 46053 | K2: 46144 | L2: 46235 | Q2: 43862 | R2: 44226 | S2: 44590 | T2: 44954 | U2: 45325 | V2: 45689 | W2: 46053
C3: Q124 | D3: Q224 | E3: Q324 | F3: Q424 | G3: Q125 | H3: Q225 | I3: Q325 | J3: Q425 | K3: Q126 | L3: Q226 | M3: Q326 | N3: Q426 | Q3: 2019 | R3: 2020 | S3: 2021 | T3: 2022 | U3: 2023 | V3: 2024 | W3: =V3+1 -> 2025 | X3: =W3+1 -> 2026 | Y3: =X3+1 -> 2027 | Z3: =Y3+1 -> 2028 | AA3: =Z3+1 -> 2029 | AB3: =AA3+1 -> 2030 | AC3: =AB3+1 -> 2031 | AD3: =AC3+1 -> 2032 | ... AG3: =AF3+1 -> 2035
B4: Store Count | C4: 2127 | D4: 2148 | E4: 2192 | F4: 2186 | G4: 2205 | H4: 2233 | I4: 2273 | J4: 2267 | K4: 2282 | L4: 2328 | M4: =M8/L5 -> 2289.4116 | N4: 2350 | Q4: 1805 | R4: 1859 | S4: 1923 | T4: 2015 | U4: 2109 | V4: 2186 | W4: 2267 | X4: =N4 -> 2350 | Y4: =2450 -> 2450 | Z4: =(Y4-X4)+Y4 -> 2550 | AA4: =(Z4-Y4)+Z4 -> 2650 | AB4: =(AA4-Z4)+AA4 -> 2750 | AC4: =(AB4-AA4)+AB4 -> 2850 | AD4: =(AC4-AB4)+AC4 -> 2950 | AE4: =(AD4-AC4)+AD4 -> 3050 | AF4: =(AE4-AD4)+AE4 -> 3150 | AG4: =(AF4-AE4)+AF4 -> 3250
B5: Revenue Per Store | C5: =C8/C4 -> 2.2839995 | D5: =D8/D4 -> 2.461601 | E5: =E8/E4 -> 2.3135739 | F5: =F8/F4 -> 2.7046107 | G5: =G8/G4 -> 2.2607578 | H5: =H8/H4 -> 2.4761093 | I5: =I8/I4 -> 2.4641205 | J5: =J8/J4 -> 2.9269916 | ... N5: =N8/N4 -> 3.105974 | Q5: =Q8/Q4 -> 8.885913 | R5: =R8/R4 -> 6.7410247 | S5: =S8/S4 -> 9.8368404 | T5: =T8/T4 -> 9.278327 | U5: =U8/U4 -> 9.6618971 | V5: =V8/V4 -> 9.6656995 | W5: =W8/W4 -> 10.035536 | X5: =X8/X4 -> 10.951252 | Y5: =X5 -> 10.951252 | Z5: =Y5 -> 10.951252 | AA5: =Z5 -> 10.951252 | AB5: =AA5 -> 10.951252 | AC5: =AB5 -> 10.951252 | AD5: =AC5 -> 10.951252 | AE5: =AD5 -> 10.951252 | AF5: =AE5 -> 10.951252 | AG5: =AF5 -> 10.951252
W6: =W4*W5 -> 22750.559
B7: SSS | H7: 0.02 | I7: 0.07 | J7: 0.09 | K7: 0.17 | L7: 0.1 | Q7: 0.03 | R7: n/a | S7: 0.13 | T7: -0.04 | U7: 0.05 | V7: 0.03 | W7: 0.05 | X7: 0.06
B8: Net Sales | C8: 4858.067 | D8: 5287.519 | E8: 5071.354 | F8: =V8-sum(C8:E8) -> 5912.279 | G8: 4984.971 | H8: 5529.152 | I8: 5600.946 | J8: =W8-sum(G8:I8) -> 6635.49 | K8: 6010.476 | L8: 6264.886 | M8: =I8*1.1 -> 6161.0406 | N8: =J8*1.1 -> 7299.039 | Q8: 16039.073 | R8: 12531.565 | S8: 18916.244 | T8: 18695.829 | U8: 20376.941 | V8: 21129.219 | W8: 22750.559 | X8: =sum(K8:N8) -> 25735.442 | Y8: =X8*1.12 -> 28823.695 | Z8: =Y8*1.12 -> 32282.538 | AA8: =Z8*1.12 -> 36156.442 | AB8: =AA8*1.12 -> 40495.216 | AC8: =AB8*1.12 -> 45354.641 | AD8: =AC8*1.12 -> 50797.198 | AE8: =AD8*1.12 -> 56892.862 | AF8: =AE8*1.12 -> 63720.006 | AG8: =AF8*1.12 -> 71366.406
B9: COGS | C9: 3490.672 | D9: 3791.929 | E9: 3634.283 | F9: =V9-sum(C9:E9) -> 4343.622 | G9: 3581.366 | H9: 4002.167 | I9: 4032.446 | J9: =W9-sum(G9:I9) -> 4831.277 | K9: 4230.589 | L9: 4145.215 | M9: =M$8*(I9/I$8) -> 4435.6906 | N9: =N$8*(J9/J$8) -> 5314.4047 | Q9: 11536.187 | R9: 9838.574 | S9: 13708.907 | T9: 13946.23 | U9: 14801.601 | V9: 15260.506 | W9: 16447.256 | X9: =sum(K9:N9) -> 18125.899 | Y9: =Y$8*(X9/X$8) -> 20301.007 | Z9: =Z$8*(Y9/Y$8) -> 22737.128 | AA9: =AA$8*(Z9/Z$8) -> 25465.583 | AB9: =AB$8*(AA9/AA$8) -> 28521.453 | AC9: =AC$8*(AB9/AB$8) -> 31944.028 | AD9: =AD$8*(AC9/AC$8) -> 35777.311 | AE9: =AE$8*(AD9/AD$8) -> 40070.589 | AF9: =AF$8*(AE9/AE$8) -> 44879.059 | AG9: =AG$8*(AF9/AF$8) -> 50264.546
B10: SG&A | C10: 776.282 | D10: 836.357 | E10: 832.855 | F10: =V10-sum(C10:E10) -> 837.633 | G10: 797.135 | H10: 888.711 | I10: 920.002 | J10: =W10-sum(G10:I10) -> 990.098 | K10: 975.861 | L10: 1016.053 | M10: =M$8*(I10/I$8) -> 1012.0022 | N10: =N$8*(J10/J$8) -> 1089.1078 | Q10: 2356.704 | R10: 2503.281 | S10: 2874.469 | T10: 2759.268 | U10: 3267.677 | V10: 3283.127 | W10: 3595.946 | X10: =sum(K10:N10) -> 4093.024 | Y10: =Y$8*(X10/X$8) -> 4584.1869 | Z10: =Z$8*(Y10/Y$8) -> 5134.2893 | AA10: =AA$8*(Z10/Z$8) -> 5750.404 | AB10: =AB$8*(AA10/AA$8) -> 6440.4525 | AC10: =AC$8*(AB10/AB$8) -> 7213.3068 | AD10: =AD$8*(AC10/AC$8) -> 8078.9036 | AE10: =AE$8*(AD10/AD$8) -> 9048.3721 | AF10: =AF$8*(AE10/AE$8) -> 10134.177 | AG10: =AG$8*(AF10/AF$8) -> 11350.278
B11: Operating Income | C11: =C8-sum(C9:C10) -> 591.113 | D11: =D8-sum(D9:D10) -> 659.233 | E11: =E8-sum(E9:E10) -> 604.216 | F11: =F8-sum(F9:F10) -> 731.024 | G11: =G8-sum(G9:G10) -> 606.47 | H11: =H8-sum(H9:H10) -> 638.274 | I11: =I8-sum(I9:I10) -> 648.498 | J11: =J8-sum(J9:J10) -> 814.115 | ... N11: =N8-sum(N9:N10) -> 895.5265 | Q11: =Q8-sum(Q9:Q10) -> 2146.182 | R11: =R8-sum(R9:R10) -> 189.71 | S11: =S8-sum(S9:S10) -> 2332.868 | T11: =T8-sum(T9:T10) -> 1990.331 | U11: =U8-sum(U9:U10) -> 2307.663 | V11: =V8-sum(V9:V10) -> 2585.586 | W11: =W8-sum(W9:W10) -> 2707.357 | X11: =X8-sum(X9:X10) -> 3516.5183 | ... AG11: =AG8-sum(AG9:AG10) -> 9751.5822
B12: Interest Income, Net | C12: -45.95 | D12: -43.35 | E12: -42.527 | F12: =V12-sum(C12:E12) -> -39.741 | G12: -34.409 | H12: -32.346 | I12: -33.9 | J12: =W12-sum(G12:I12) -> -34.145 | K12: -33.449 | L12: -31.144 | M12: =AVERAGE(I12:L12) -> -33.1595 | N12: =AVERAGE(J12:M12) -> -32.974375 | Q12: -18.106 | R12: 83.413 | S12: 74.328 | T12: 2.842 | U12: -164.118 | V12: -171.568 | W12: -134.8 | X12: =W25*$AL$18 -> -140.07568 | Y12: =X25*$AL$18 -> -141.47644 | Z12: =Y25*$AL$18 -> -142.89121 | AA12: =Z25*$AL$18 -> -144.32012 | AB12: =AA25*$AL$18 -> -145.76332 | AC12: =AB25*$AL$18 -> -147.22095 | AD12: =AC25*$AL$18 -> -148.69316 | AE12: =AD25*$AL$18 -> -150.18009 | ... AG12: =AF25*$AL$18 -> -153.19871
B13: Earnings Before Taxes | C13: =C11-C12 -> 637.063 | D13: =D11-D12 -> 702.583 | E13: =E11-E12 -> 646.743 | F13: =F11-F12 -> 770.765 | G13: =G11-G12 -> 640.879 | H13: =H11-H12 -> 670.62 | I13: =I11-I12 -> 682.398 | J13: =J11-J12 -> 848.26 | ... N13: =N11-N12 -> 928.50087 | Q13: =Q11-Q12 -> 2164.288 | R13: =R11-R12 -> 106.297 | S13: =S11-S12 -> 2258.54 | T13: =T11-T12 -> 1987.489 | U13: =U11-U12 -> 2471.781 | V13: =V11-V12 -> 2757.154 | W13: =W11-W12 -> 2842.157 | X13: =X11-X12 -> 3656.594 | ... AG13: =AG11-AG12 -> 9904.7809
B14: Taxes | C14: 149.073 | D14: 175.435 | E14: 157.935 | F14: =V14-sum(C14:E14) -> 183.981 | G14: 161.63 | H14: 162.625 | I14: 170.643 | J14: =W14-sum(G14:I14) -> 202.215 | K14: 187.511 | L14: 283.463 | M14: =M13*(L14/L13) -> 186.47716 | N14: =N13*(M14/M13) -> 231.93907 | Q14: 503.36 | R14: 20.915 | S14: 535.951 | T14: 475.448 | U14: 597.261 | V14: 666.424 | W14: 697.113 | X14: =sum(K14:N14) -> 889.39023 | Y14: =Y13*(X14/X13) -> 992.36931 | Z14: =Z13*(Y14/Y13) -> 1107.6684 | AA14: =AA13*(Z14/Z13) -> 1236.7655 | AB14: =AB13*(AA14/AA13) -> 1381.3161 | AC14: =AC13*(AB14/AB13) -> 1543.1741 | AD14: =AD13*(AC14/AC13) -> 1724.416 | AE14: =AE13*(AD14/AD13) -> 1927.3676 | AF14: =AF13*(AE14/AE13) -> 2154.6336 | AG14: =AG13*(AF14/AF13) -> 2409.1314
B15: Net Income | C15: =C13-C14 -> 487.99 | D15: =D13-D14 -> 527.148 | E15: =E13-E14 -> 488.808 | F15: =F13-F14 -> 586.784 | G15: =G13-G14 -> 479.249 | H15: =H13-H14 -> 507.995 | I15: =I13-I14 -> 511.755 | J15: =J13-J14 -> 646.045 | ... N15: =N13-N14 -> 696.5618 | Q15: =Q13-Q14 -> 1660.928 | R15: =R13-R14 -> 85.382 | S15: =S13-S14 -> 1722.589 | T15: =T13-T14 -> 1512.041 | U15: =U13-U14 -> 1874.52 | V15: =V13-V14 -> 2090.73 | W15: =W13-W14 -> 2145.044 | X15: =X13-X14 -> 2767.2038 | ... AG15: =AG13-AG14 -> 7495.6495 | AH15: =AG15*(1+$AL$19) -> 7570.606 | AI15: =AH15*(1+$AL$19) -> 7646.3121 | AJ15: =AI15*(1+$AL$19) -> 7722.7752 | AK15: =AJ15*(1+$AL$19) -> 7800.0029 | AL15: =AK15*(1+$AL$19) -> 7878.003 | AM15: =AL15*(1+$AL$19) -> 7956.783 | AN15: =AM15*(1+$AL$19) -> 8036.3508 | AO15: =AN15*(1+$AL$19) -> 8116.7143 | ... GV15: =GU15*(1+$AL$19) -> 41092.654
B16: Diluted | C16: 333.737 | D16: 331.511 | E16: 329.937 | F16: =F15/F17 -> 329.12614 | G16: 327.005 | H16: 324.796 | I16: 323.297 | J16: =J15/J17 -> 323.10695 | K16: 321.231 | L16: 319.45 | M16: =L16 -> 319.45 | N16: =M16 -> 319.45 | Q16: 361.182 | R16: 354.619 | S16: 353.734 | T16: 345.222 | U16: 337.433 | V16: 330.984 | W16: 324.416 | X16: =X15/X17 -> 320.95228 | Y16: =X16 -> 320.95228 | Z16: =Y16 -> 320.95228 | AA16: =Z16 -> 320.95228 | AB16: =AA16 -> 320.95228 | AC16: =AB16 -> 320.95228 | AD16: =AC16 -> 320.95228 | AE16: =AD16 -> 320.95228 | AF16: =AE16 -> 320.95228 | AG16: =AF16 -> 320.95228
B17: EPS | C17: =C15/C16 -> 1.4621993 | D17: =D15/D16 -> 1.5901373 | E17: =E15/E16 -> 1.4815192 | F17: =V17-sum(C17:E17) -> 1.7828544 | G17: =G15/G16 -> 1.4655709 | H17: =H15/H16 -> 1.5640433 | I17: =I15/I16 -> 1.5829253 | J17: =W17-sum(G17:I17) -> 1.9994772 | K17: =K15/K16 -> 2.0233539 | L17: =L15/L16 -> 2.6648897 | M17: =M15/M16 -> 1.7531073 | N17: =N15/N16 -> 2.1805034 | Q17: =Q15/Q16 -> 4.5985902 | R17: =R15/R16 -> 0.24077108 | S17: =S15/S16 -> 4.8697298 | T17: =T15/T16 -> 4.3799092 | U17: =U15/U16 -> 5.5552362 | V17: =V15/V16 -> 6.3167102 | W17: =W15/W16 -> 6.6120167 | X17: =sum(K17:N17) -> 8.6218543 | Y17: =Y15/Y16 -> 9.6201456 | Z17: =Z15/Z16 -> 10.737869 | AA17: =AA15/AA16 -> 11.989351 | AB17: =AB15/AB16 -> 13.390642 | AC17: =AC15/AC16 -> 14.959712 | AD17: =AD15/AD16 -> 16.716693 | AE17: =AE15/AE16 -> 18.68413 | AF17: =AF15/AF16 -> 20.887274 | AG17: =AG15/AG16 -> 23.354405
AK18: ROIC | AL18: -0.045
B19: Growth YY | AK19: Discount | AL19: 0.01
B20: Net Sales | G20: =G8/C8-1 -> 0.026122324 | H20: =H8/D8-1 -> 0.045698748 | I20: =I8/E8-1 -> 0.10442813 | J20: =J8/F8-1 -> 0.12232356 | K20: =K8/G8-1 -> 0.20571935 | L20: =L8/H8-1 -> 0.13306453 | M20: =M8/I8-1 -> 0.1 | N20: =N8/J8-1 -> 0.1 | R20: =R8/Q8-1 -> -0.21868521 | S20: =S8/R8-1 -> 0.50948776 | T20: =T8/S8-1 -> -0.011652155 | U20: =U8/T8-1 -> 0.089919094 | V20: =V8/U8-1 -> 0.036918103 | W20: =W8/V8-1 -> 0.076734497 | X20: =X8/W8-1 -> 0.13120041 | Y20: =Y8/X8-1 -> 0.12 | ... AG20: =AG8/AF8-1 -> 0.12 | AK20: Maturity | AL20: 0.08
B21: Gross Margin | C21: =(C8-C9)/C8 -> 0.28146895 | D21: =(D8-D9)/D8 -> 0.28285288 | E21: =(E8-E9)/E8 -> 0.28337028 | F21: =(F8-F9)/F8 -> 0.26532188 | G21: =(G8-G9)/G8 -> 0.28156734 | H21: =(H8-H9)/H8 -> 0.27616984 | I21: =(I8-I9)/I8 -> 0.28004198 | J21: =(J8-J9)/J8 -> 0.27190351 | ... N21: =(N8-N9)/N8 -> 0.27190351 | Q21: =(Q8-Q9)/Q8 -> 0.28074478 | R21: =(R8-R9)/R8 -> 0.21489662 | S21: =(S8-S9)/S8 -> 0.27528388 | T21: =(T8-T9)/T8 -> 0.25404592 | U21: =(U8-U9)/U8 -> 0.27361025 | V21: =(V8-V9)/V8 -> 0.27775343 | W21: =(W8-W9)/W8 -> 0.27706146 | X21: =(X8-X9)/X8 -> 0.29568338 | ... AG21: =(AG8-AG9)/AG8 -> 0.29568338 | AK21: NPV | AL21: {=NPV(AL20,X15:GV15)} -> 80014.699
B22: Operating Margin | C22: =C11/C8 -> 0.12167658 | D22: =D11/D8 -> 0.12467719 | E22: =E11/E8 -> 0.11914294 | F22: =F11/F8 -> 0.12364504 | G22: =G11/G8 -> 0.12165968 | H22: =H11/H8 -> 0.11543795 | I22: =I11/I8 -> 0.11578366 | J22: =J11/J8 -> 0.12269101 | ... N22: =N11/N8 -> 0.12269101 | Q22: =Q11/Q8 -> 0.1338096 | R22: =R11/R8 -> 0.015138572 | S22: =S11/S8 -> 0.12332617 | T22: =T11/T8 -> 0.10645856 | U22: =U11/U8 -> 0.11324875 | V22: =V11/V8 -> 0.12237016 | W22: =W11/W8 -> 0.11900178 | X22: =X11/X8 -> 0.13664107 | ... AG22: =AG11/AG8 -> 0.13664107 | AK22: Shares | AL22: =Main!K4 -> 319.45
AK23: Estimate | AL23: =AL21/AL22 -> 250.47644
AK24: Current | AL24: =Main!K3 -> 248.58
B25: Cash | F25: 4730.744 | G25: 3783.413 | H25: 3847.016 | I25: 4061.173 | J25: 4594.392 | K25: 4130.98 | L25: 4288.124 | W25: =K49 -> 3112.793 | X25: =W25*1.01 -> 3143.9209 | Y25: =X25*1.01 -> 3175.3601 | Z25: =Y25*1.01 -> 3207.1137 | AA25: =Z25*1.01 -> 3239.1849 | AB25: =AA25*1.01 -> 3271.5767 | AC25: =AB25*1.01 -> 3304.2925 | AD25: =AC25*1.01 -> 3337.3354 | AE25: =AD25*1.01 -> 3370.7088 | ... AG25: =AF25*1.01 -> 3438.46 | AK25: Upside | AL25: =AL23/AL24-1 -> 0.0076290957
B26: A/R | F26: 144.482 | G26: 181.004 | H26: 210.52 | I26: 203.891 | J26: 181.301 | K26: 212.54 | L26: 248.14
B27: Merch Inventory | F27: 2444.513 | G27: 2669.849 | H27: 2608.485 | I27: 3128.971 | J27: 2630.97 | K27: 2976.958 | L27: 3087.37
B28: Prepaid Expense | F28: 218.957 | G28: 240.837 | H28: 259.815 | I28: 235.617 | J28: 233.434 | K28: 252.941 | L28: 252.726
B29: PPE | F29: 3792.403 | G29: 3827.541 | H29: 3906.34 | I29: 3987.247 | J29: 4088.76 | K29: 4147.666 | L29: 4257.806
B30: Op Lease | F30: 3294.858 | G30: 3325.849 | H30: 3374.582 | I30: 3498.077 | J30: 3519.61 | K30: 3531.945 | L30: 3545.351
B31: OLTA | F31: 279.375 | G31: 276.123 | H31: 288.761 | I31: 299.99 | J31: 300.27 | K31: 301.542 | L31: 302.763
B32: Total Assets | F32: =sum(F25:F31) -> 14905.332 | G32: =sum(G25:G31) -> 14304.616 | H32: =sum(H25:H31) -> 14495.519 | I32: =sum(I25:I31) -> 15414.966 | J32: =sum(J25:J31) -> 15548.737 | K32: =sum(K25:K31) -> 15554.572 | L32: =sum(L25:L31) -> 15982.28
B34: A/P | F34: 2126.317 | G34: 2163.954 | H34: 2205.613 | I34: 2645.234 | J34: 2386.418 | K34: 2653.741 | L34: 2621.74
B35: Accrued Exp | F35: 626.49 | G35: 616.008 | H35: 655.218 | I35: 689.539 | J35: 666.978 | K35: 696.511 | L35: 744.284
B36: Current Op Lease | F36: 703.337 | G36: 702.025 | H36: 716.162 | I36: 723.512 | J36: 727.855 | K36: 735.528 | L36: 752.302
B37: Acrued Payroll | F37: 462.284 | G37: 274.877 | H37: 315.893 | I37: 438.989 | J37: 484.407 | K37: 376.76 | L37: 440.837
B38: Income Taxes Payable | F38: 43.666 | G38: 180.083 | H38: 0 | I38: 23.08 | J38: 61.779 | K38: 210.971 | L38: 84.916
B39: Current Debt | F39: 699.731 | G39: 498.812 | H39: 499.122 | I39: 499.432 | J39: 499.743 | K39: 241.344 | L39: 241.459
B40: LTD | F40: 1515.08 | G40: 1016.897 | H40: 1017.218 | I40: 1017.54 | J40: 1017.863 | K40: 776.843 | L40: 777.053
B41: NC Op Lease | F41: 2764.281 | G41: 2797.935 | H41: 2835.481 | I41: 2948.105 | J41: 2966.877 | K41: 2969.435 | L41: 2968.337
...

Sheet Bonds
A1: Main | E1: =TODAY() -> 46257 | F1: 100
B2: Ticker | C2: Clean Price | D2: Coupon | E2: Maturity | F2: Time Remaining | G2: Remaining Coupons | H2: Net Coupon Income | I2: Capital Gains | J2: Total Return | K2: IRR | M2: Remaining
B3: ROST | C3: 88.059 | D3: 0.0545 | E3: 54893 | F3: =ROUND((E3-$E$1)/365,0) -> 24 | G3: =F3*2 -> 48 | H3: =($F$1 * D3) * F3 -> 130.8 | I3: =($F$1-C3) -> 11.941 | J3: =sum(H3:I3) -> 142.741 | K3: =YIELD($E$1,E3,D3,C3,$F$1,2) -> 0.064394547 | M3: 146558 | N3: LT
B4: ROST | C4: 87.574 | D4: 0.01875 | E4: 47953 | F4: =ROUND((E4-$E$1)/365,0) -> 5 | G4: =F4*2 -> 10 | H4: =($F$1 * D4) * F4 -> 9.375 | I4: =($F$1-C4) -> 12.426 | J4: =sum(H4:I4) -> 21.801 | K4: =YIELD($E$1,E4,D4,C4,$F$1,2) -> 0.048982345 | M4: 497106 | N4: LT
B5: ROST | C5: 98.491 | D5: 0.048 | E5: 47588 | F5: =ROUND((E5-$E$1)/365,0) -> 4 | G5: =F5*2 -> 8 | H5: =($F$1 * D5) * F5 -> 19.2 | I5: =($F$1-C5) -> 1.509 | J5: =sum(H5:I5) -> 20.709 | K5: =YIELD($E$1,E5,D5,C5,$F$1,2) -> 0.052584441 | M5: 133179 | N5: LT
B6: ROST | C6: 99.937 | D6: 0.047 | E6: 46492 | F6: =ROUND((E6-$E$1)/365,0) -> 1 | G6: =F6*2 -> 2 | H6: =($F$1 * D6) * F6 -> 4.7 | I6: =($F$1-C6) -> 0.063 | J6: =sum(H6:I6) -> 4.763 | K6: =YIELD($E$1,E6,D6,C6,$F$1,2) -> 0.047913161 | M6: 241344 | N6: Current
B11: Debt Exhibit
B12: 4.7, 4.8, 5.45 note
B13: 1.875 note
B14: 0.875 note
