Workbook

Sheet Main
B1: Company: American Integrity Insurance Group Inc
B2: Subsidiary: American Integrity Insurance Group
B3: Provides: Residential Property Insurance
B4: Seeded By: Sowell & Co: https://www.sowellco.com/ | J4: P | K4: 16.6
B5: CEO: Robert Ritchie | J5: S | K5: 19.590817 | L5: Q126
B6: CFO: Brian Foley; former: Ben Lurie | J6: MC | K6: =+K4*K5 -> 325.20756
B7: HQ: Tampa FL | J7: C | K7: =171.182+55.169 -> 226.351 | L7: =+L5 -> Q126 | Z7: Catastrophe Reinsurance Tower
B8: Founded 2006 | J8: D | K8: 0.515 | L8: =+L7 -> Q126 | Z8: A. Primary Retention; the deductible AII keeps. Before reinsurers pay AII absorbs 1st $35M ($10M = Insurance Exposure; $25M = Captive Exposure)
B9: IPO: 2025 | J9: EV | K9: =+K6-K7+K8 -> 99.371562 | Z9: B. Co-Participation Layer. AII still shares some losses even after reinsurers begin to pay. (3rd event retention = $16M; 4th Event retention = $10M)
B10: Hurricane Szn: June 1st - Nov 30th | Z10: C. Florida Hurricane Catastrophe Fund (FHCF) - state sponsored reinsruance. Mandatory for state of FL residential insurers.
B11: Internal Software: ouchstone from AIR (Verisk), Risk Modeler from RMS (Moody’s), RiskInsight from Karen Clark & Company, Opterrix | J11: CPS | K11: =+K7/K5 -> 11.553934 | Z11: D. Class D CAT bond placed in 2025. Investors buy bonds, if no catastrophe --> earns interest, if catastrophe, loses principal)
B12: Employees: 313 as of 12/31/2026 | J12: BVPS | K12: =+K13/K5 -> 17.124503 | Z12: E. Multi-Tranche CAT bond (Expires May 2026) - additional Capital market reinsurance
J13: BV | K13: =+Model!K77/1000 -> 335.483 | L13: =+K13-35 -> 300.483 | Z13: F. Class C CAT bond placed in 2024 expiring end of May 2026
K14: =+K6/K13 -> 0.96937121 | L14: =+L13/K5 -> 15.337951 | Z14: G. Class C CAT bond, expiring May 2027
B15: Susbsidiaries | Z15: H. Multi-Tranche CAT bond (Expires May 2027)
B16: American Integrity Insurance Group, LLC (AIIG), holding company formed in Texas in 2006 | Z16: I. Multi-tranche CAT bond placed in 2025 expiring end of May 2028
B17: American Integrity Insurance Company (AIIC) is a corporation that operates as a Florida-domiciled admitted insurance company. Core ops performed by other subsidiaries, but employs accounting dept | Z17: J. Probability of an event occuring in any given year that exausts the tower
B18: American Integrity MGA, LLC (AIMGA) operates as a Texas domiciled managing general agency to produce, underwrite, negotiate, bind, and administer policies | Z18: 0.0076923077
B19: American Integrity Claims Services, LLC (AICS) manages all non-catastrophe claims for AIIC and, on an as needed basis,
B20: Pinnacle Analytics, LLC (Pinnacle) is responsible for performing ongoing reinsurance related analytical and modeling
B21: Pinnacle Insurance Consultants, LLC (PIC) acts as the agent of record of policies that are assumed from Citizens | Z21: Expected value of the Third Event exposure
Z22: Known
B23: News | C23: Contains | D23: Earnings | E23: Earnings Transcript | Z23: third event retention is $85M ater $10M
B24: 46148 | C24: Increasing Total Insured Value | D24: Q425 | Z24: Florida averages ~1.5 per year historically
B25: 46118 | C25: New CFO | D25: Q325 | Z25: Probablity of 3+ named storms hitting Florida in one season :
D26: Q225 | Z26: P(1st tower exhausted) = 1/130 or 0.77% in any given year
D27: Q125 | Z27: P(second tower stressed) = P(first event) * P(second event | 1st tower exhausted) = 0.0077 * .093 = .07%
Z28: P(third event) = .0077 * 0.25 = 0.179%
Z32: =+Z34*0.25 -> 0.00017884615 | AA32: =1/Z32 -> 5591.3978
Z33: 0.0076923077
Z34: =+Z33*0.093 -> 0.00071538462
B49: Triangle: Incurred Losses and Allocated LAE, Net of Reinsurance ($k)
B50: Accident Year | C50: 2015 | D50: =+C50+1 -> 2016 | E50: =+D50+1 -> 2017 | F50: =+E50+1 -> 2018 | G50: =+F50+1 -> 2019 | H50: =+G50+1 -> 2020 | I50: =+H50+1 -> 2021 | J50: =+I50+1 -> 2022 | K50: =+J50+1 -> 2023 | ... M50: =+L50+1 -> 2025 | N50: Reported remainig | O50: Model Remaining
B51: 2015 | C51: 42003 | D51: 39623 | E51: 46877 | F51: 47555 | G51: 48545 | H51: 48672 | I51: 48426 | J51: 48853 | K51: 49012 | L51: 48895 | M51: 49086 | N51: 19 | O51: =+M51-M66 -> 119
B52: =+B51+1 -> 2016 | D52: 53192 | E52: 51879 | F52: 54306 | G52: 56499 | H52: 57282 | I52: 60983 | J52: 61206 | K52: 61568 | L52: 60855 | M52: 60791 | N52: 66 | O52: =+M52-M67 -> 64
B53: =+B52+1 -> 2017 | E53: 57286 | F53: 48820 | G53: 26956 | H53: 24139 | I53: 22535 | J53: 18846 | K53: 19453 | L53: 19172 | M53: 19363 | N53: 25 | O53: =+M53-M68 -> 17
B54: =+B53+1 -> 2018 | F54: 89565 | G54: 78270 | H54: 82013 | I54: 86354 | J54: 83734 | K54: 84985 | L54: 83191 | M54: 83072 | N54: 72 | O54: =+M54-M69 -> 61
B55: =+B54+1 -> 2019 | G55: 104651 | H55: 107979 | I55: 118580 | J55: 118187 | K55: 121378 | L55: 119509 | M55: 118987 | N55: 553 | O55: =+M55-M70 -> 454
B56: =+B55+1 -> 2020 | H56: 93727 | I56: 133001 | J56: 134531 | K56: 140552 | L56: 139361 | M56: 139337 | N56: 1344 | O56: =+M56-M71 -> 1178
B57: =+B56+1 -> 2021 | I57: 78605 | J57: 110218 | K57: 114801 | L57: 116366 | M57: 116347 | N57: 2008 | O57: =+M57-M72 -> 1741
...

Sheet Reinsurer
B3: Reinsurer | C3: 46022 | D3: Rating
B4: Horshoe Re Ltd | C4: 32280 | D4: Collaterized
B5: National Liability & Fire Insurance Co. | C5: 30000 | D5: A++
B6: Insurance Company Of The West | C6: 21944 | D6: A
B7: Hanover Rück SE | C7: 20837 | D7: A+
B8: Arch Reinsurance Ltd | C8: 15243 | D8: A+
B9: Ada Re | C9: 14332 | D9: Collaterized
B10: Renaissance Reinsurance Limited | C10: 13386 | D10: A+
B11: DaVinci Reinsurance Corporation | C11: 13345 | D11: A
B12: General Reinsurance Company | C12: 10842 | D12: A++
B13: Transatlantic Reinsurance Company | C13: 10105 | D13: A++
B14: Top 10 Total | C14: =+SUM(C4:C13) -> 182314
B15: All Others | C15: 86742
B16: Florida Hurricane Catastrophe Fund (FHCF) | C16: 0
B17: Total | C17: =+SUM(C14:C16) -> 269056
B20: Rating Agencies | C20: Rating
B21: Demotech | C21: A
B22: Kross Bond Rating Agency, LLC | C22: BBB+
B24: Actuary methods
B25: Bornhuetter-Ferguson
B30: December 2025
B31: County | C31: PIF | D31: Net In-Force Premium | E31: Total Insured Value | F31: Ocean
B32: Polk | C32: 27335 | D32: 47538 | E32: 13975 | F32: Gulf
B33: Lee | C33: 25996 | D33: 67600 | E33: 14608 | F33: Gulf
B34: Orange | C34: 25977 | D34: 57361 | E34: 14422 | F34: Central FL
B35: Duval | C35: 22845 | D35: 36933 | E35: 11936 | F35: Atlantic
B36: Hillsborough | C36: 21134 | D36: 49781 | E36: 12917 | F36: Gulf
B37: Osceola | C37: 20201 | D37: 41866 | E37: 10539 | F37: Atlantic
B38: Pasco | C38: 20104 | D38: 39846 | E38: 12937 | F38: Gulf
B39: Palm Beach | C39: 19093 | D39: 73301 | E39: 8289 | F39: Atlantic
B40: Marion | C40: 17007 | D40: 23660 | E40: 8574 | F40: Central FL
B41: Brevard | C41: 14655 | D41: 36223 | E41: 7685 | F41: Atlantic
B42: Volusia | C42: 13478 | D42: 28119 | E42: 7249 | F42: Atlantic
B43: Others | C43: 167309 | D43: 446395 | E43: 91651
B44: Total | C44: =SUM(C32:C43) -> 395134 | D44: =SUM(D32:D43) -> 948623 | E44: =SUM(E32:E43) -> 214782

Sheet Hurricane Szns
I2: =COUNTA(B6:B54) -> 43
B3: Florida major hurricanes | E3: {=range(E6:E54)} -> #NAME?
B4: Storm | C4: Saffir–Simpson | D4: Date of Impact | E4: Year | F4: Landfall Winds | G4: Location(s) | I4: 2004 ==3
C5: Category† | D5: (UTC) | F5: (in Knots) | I5: 2024 == 2
B6: Alma | C6: 3 | D6: 46181 | E6: 1966 | F6: 100 | G6: Dry Tortugas* | I6: 2005 == 2
B7: Andrew | C7: 5 | D7: 46258 | E7: 1992 | F7: 145 | G7: Elliott Key | I7: 1950 == 2
G8: North of Homestead | I8: 9
B9: Betsy | C9: 3 | D9: 46273 | E9: 1965 | F9: 100 | G9: Tavernier
B10: Charley | C10: 4 | D10: 46247 | E10: 2004 | F10: 130 | G10: Cayo Costa
G11: Punta Gorda | I11: P(2nd storm | 1st storm already hit)
B12: Dennis | C12: 3 | D12: 46213 | E12: 2005 | F12: 105 | G12: Santa Rosa Island | I12: =4/I2 -> 0.093023256
B13: Donna | C13: 4 | D13: 46275 | E13: 1960 | F13: 125 | G13: Conch Key | I13: P(3rd storm | 2 storms already hit)
B14: Easy | C14: 3 | D14: 46270 | E14: 1950 | F14: 105 | G14: East of Cedar Key | I14: =1/4 -> 0.25
B15: Elena | C15: 3 | D15: 46267 | E15: 1985 | F15: 100 | G15: Gulfport, Mississippi*
B16: Eloise | C16: 3 | D16: 46288 | E16: 1975 | F16: 110 | G16: East of Destin
B17: Florida Keys | C17: 4 | D17: 46275 | E17: 1919 | F17: 130 | G17: Dry Tortugas
B18: Great Miami | C18: 4 | D18: September 18–20 | E18: 1926 | F18: 125 | G18: Perrine
B19: Great Middle Florida | C19: 3 | D19: 46257 | E19: 1851 | F19: 100 | G19: Panama City
B20: Helene | C20: 4 | D20: 46292 | E20: 2024 | F20: 120 | G20: Southwest of Perry
B21: Ian | C21: 4 | D21: 46293 | E21: 2022 | F21: 130 | G21: Cayo Costa
G22: Punta Gorda
B23: Idalia | C23: 3 | D23: 46264 | E23: 2023 | F23: 100 | G23: Keaton Beach
B24: Irma | C24: 4 | D24: 46275 | E24: 2017 | F24: 115 | G24: Cudjoe Key
G25: Marco Island
B26: Ivan | C26: 3 | D26: 46281 | E26: 2004 | F26: 105 | G26: West of Gulf Shores, Alabama*
B27: Jeanne | C27: 3 | D27: 46291 | E27: 2004 | F27: 105 | G27: Hutchinson Island
B28: King | C28: 4 | D28: 46313 | E28: 1950 | F28: 115 | G28: Miami
B29: Labor Day | C29: 5 | D29: 46268 | E29: 1935 | F29: 160 | G29: Craig Key
B30: Michael | C30: 5 | D30: 46305 | E30: 2018 | F30: 140 | G30: West of Mexico Beach
B31: Milton | C31: 3 | D31: 46304 | E31: 2024 | F31: 100 | G31: Siesta Key^
B32: Okeechobee | C32: 4 | D32: 46282 | E32: 1928 | F32: 125 | G32: Palm Beach
B33: Opal | C33: 3 | D33: 46299 | E33: 1995 | F33: 100 | G33: Pensacola Beach
B34: Tampa Bay | C34: 3 | D34: 46320 | E34: 1921 | F34: 100 | G34: Tarpon Springs
B35: Unnamed | C35: 3 | D35: 46251 | E35: 1871 | F35: 100 | G35: Jupiter Island
B36: Unnamed | C36: 3 | D36: 46302 | E36: 1873 | F36: 100 | G36: Captiva Island
B37: Unnamed | C37: 3 | D37: 46298 | E37: 1877 | F37: 100 | G37: Panama City
... B42: Unnamed | C42: 3 | D42: 46313 | E42: 1906 | F42: 105 | G42: Marathon
G43: East of Flamingo
B44: Unnamed | C44: 3 | D44: 46306 | E44: 1909 | F44: 100 | G44: Marathon
B45: Unnamed | C45: 3 | D45: 46294 | E45: 1917 | F45: 100 | G45: Fort Walton Beach
...

Sheet Readings
B3: Read(x) | C3: Florida Public Hurricane Loss Model https://eei.fiu.edu/_assets/images/hamid.pdf
C4: Normalized Hurricane Damage in the US: 1900-2022
C5: KCC US Hurricane Ref Model
C6: U.S. Property-Casualty: Underwriting Cycle Modeling and Risk Benchmarks
C7: Distributions for Actuaries

Sheet Model
C3: Q124 | D3: Q224 | E3: Q324 | F3: Q424 | G3: Q125 | H3: Q225 | I3: Q325 | J3: Q425 | K3: Q126 | L3: Q226 | M3: Q326 | N3: Q426 | Q3: 2019 | R3: =+Q3+1 -> 2020 | S3: =+R3+1 -> 2021 | T3: =+S3+1 -> 2022 | U3: =+T3+1 -> 2023 | V3: =+U3+1 -> 2024 | W3: =+V3+1 -> 2025 | X3: =+W3+1 -> 2026 | Y3: =+X3+1 -> 2027 | ... FO3: =+FN3+1 -> 2173
B4: Loss Ratio | C4: =+C30/SUM(C24:C25) -> 0.49868991 | D4: =+D30/SUM(D24:D25) -> 0.29611412 | E4: =+E30/SUM(E24:E25) -> 0.59013493 | F4: =+F30/SUM(F24:F25) -> 0.51645809 | G4: =+G30/SUM(G24:G25) -> 0.30858208 | H4: =+H30/SUM(H24:H25) -> 0.30648287 | I4: =+I30/SUM(I24:I25) -> 0.5410554 | J4: =+J30/SUM(J24:J25) -> 0.42626348 | K4: =+K30/SUM(K24:K25) -> 0.37344179 | V4: =+V30/SUM(V24:V25) -> 0.4794561 | W4: =+W30/SUM(W24:W25) -> 0.38699668 | X4: =AVERAGE(0.387,0.4) -> 0.3935 | Y4: =AVERAGE(0.387,0.4) -> 0.3935 | Z4: 0.8 | AA4: =AVERAGE(0.387,0.4) -> 0.3935 | AB4: =AVERAGE(0.387,0.4) -> 0.3935 | AC4: =AVERAGE(0.387,0.4) -> 0.3935 | AD4: 0.8 | AE4: =AVERAGE(0.387,0.4) -> 0.3935 | AF4: =AVERAGE(0.387,0.4) -> 0.3935 | AG4: 0.8
B5: Expense Ratio | C5: 0.26 | D5: 0.312 | E5: 0.353 | F5: 0.371 | G5: 0.12 | H5: 0.423 | I5: 0.248 | J5: 0.202 | K5: 0.376 | V5: 0.33 | W5: 0.25 | X5: =AVERAGE(V5:W5) -> 0.29 | Y5: =AVERAGE(W5:X5) -> 0.27 | Z5: =AVERAGE(X5:Y5) -> 0.28 | AA5: =AVERAGE(Y5:Z5) -> 0.275 | AB5: =AVERAGE(Z5:AA5) -> 0.2775 | AC5: =AVERAGE(AA5:AB5) -> 0.27625 | AD5: =AVERAGE(AB5:AC5) -> 0.276875 | AE5: =AVERAGE(AC5:AD5) -> 0.2765625 | ... AG5: =AVERAGE(AE5:AF5) -> 0.27664062
B6: Combined Ratio | C6: =+SUM(C4:C5) -> 0.75868991 | D6: =+SUM(D4:D5) -> 0.60811412 | E6: =+SUM(E4:E5) -> 0.94313493 | F6: =+SUM(F4:F5) -> 0.88745809 | G6: =+SUM(G4:G5) -> 0.42858208 | H6: =+SUM(H4:H5) -> 0.72948287 | I6: =+SUM(I4:I5) -> 0.7890554 | J6: =+SUM(J4:J5) -> 0.62826348 | K6: =+SUM(K4:K5) -> 0.74944179 | V6: =+SUM(V4:V5) -> 0.8094561 | W6: =+SUM(W4:W5) -> 0.63699668 | X6: =+SUM(X4:X5) -> 0.6835 | Y6: =+SUM(Y4:Y5) -> 0.6635 | Z6: =+SUM(Z4:Z5) -> 1.08 | AA6: =+SUM(AA4:AA5) -> 0.6685 | AB6: =+SUM(AB4:AB5) -> 0.671 | AC6: =+SUM(AC4:AC5) -> 0.66975 | ... AG6: =+SUM(AG4:AG5) -> 1.0766406
B7: Ceded Catastrophe excess of Loss Premiums Ratio | C7: 0.465 | D7: 0.461 | E7: 0.468 | G7: 0.414 | H7: 0.422 | I7: 0.48 | K7: 0.466 | V7: 0.449 | W7: 0.445
B8: Underlying Loss & Loss Adjustment Expense Ratio | C8: 0.431 | D8: 0.32 | E8: 0.364 | G8: 0.3 | H8: 0.331 | I8: 0.499 | K8: 0.373 | V8: 0.326 | W8: 0.394
B9: Gross Underlying Non-Catastrophe Ratio | G9: 0.162 | K9: 0.191 | V9: 0.17 | W9: 0.17
B11: Independent Agents | S11: 390573.07 | T11: 466624.03 | U11: 531020.71 | V11: 518948.73 | W11: 479434.48
B12: Homebuilder Affiliated Agents | S12: 10856.88 | T12: 16159.555 | U12: 34770.868 | V12: 62979.829 | W12: 87497.281
B13: Insurance Companies | S13: 17843.369 | T13: 31350.203 | U13: 41544.546 | V13: 45232.533 | W13: 52023.553
B14: National Agencies | S14: 11073.5 | T14: 20670.858 | U14: 30118.604 | V14: 34172.754 | W14: 36670.698
B15: Total Voluntary In-Force Premium | S15: =+SUM(S11:S14) -> 430346.82 | T15: =+SUM(T11:T14) -> 534804.65 | U15: =+SUM(U11:U14) -> 637454.73 | V15: =+SUM(V11:V14) -> 661333.84 | W15: =+SUM(W11:W14) -> 655626.01
B16: Assumed from Citizens | S16: 30955.106 | T16: 31402.552 | U16: 34536.1 | V16: 213923.36 | W16: 292996.93
B17: In Force Premium ($k) | C17: 675486 | D17: 695238 | E17: 699213 | F17: 875257 | G17: 909539 | H17: 921252 | I17: 910404 | J17: 948623 | S17: =SUM(S15:S16) -> 461301.92 | T17: =SUM(T15:T16) -> 566207.2 | U17: =SUM(U15:U16) -> 671990.83 | V17: =SUM(V15:V16) -> 875257.2 | W17: =SUM(W15:W16) -> 948622.94
B18: FL | W18: =+Reinsurer!D44 -> 948623
B20: Gross Premiums Written | C20: 147452 | D20: 221632 | E20: 160977 | F20: 237617 | G20: 212150 | H20: 286995 | I20: 239100 | J20: 206388 | K20: 220004 | V20: 767678 | W20: 944634
B21: Change in Gross Unearned Premiums | C21: 9476 | D21: -61546 | E21: 4384 | F21: -37776 | G21: -1994 | H21: -63255 | I21: -17151 | J21: 22724 | K21: 10768 | V21: -85462 | W21: -59676
B22: Gross Premiums Earned | C22: =+C20+C21 -> 156928 | D22: =+D20+D21 -> 160086 | E22: =+E20+E21 -> 165361 | F22: =+F20+F21 -> 199841 | G22: =+G20+G21 -> 210156 | H22: =+H20+H21 -> 223740 | I22: =+I20+I21 -> 221949 | J22: =+J20+J21 -> 229112 | K22: =+K20+K21 -> 230772 | V22: =+V20+V21 -> 682216 | W22: =+W20+W21 -> 884958
B23: Ceded Premiums Earned | C23: -117645 | D23: -119567 | E23: -124897 | F23: -138052 | G23: -144754 | H23: -157571 | I23: -169950 | J23: -169760 | K23: -148564 | V23: -500161 | W23: -642035
B24: Net Premiums Earned | C24: =+C22+C23 -> 39283 | D24: =+D22+D23 -> 40519 | E24: =+E22+E23 -> 40464 | F24: =+F22+F23 -> 61789 | G24: =+G22+G23 -> 65402 | H24: =+H22+H23 -> 66169 | I24: =+I22+I23 -> 51999 | J24: =+J22+J23 -> 59352 | K24: =+K22+K23 -> 82208 | V24: =+V22+V23 -> 182055 | W24: =+W22+W23 -> 242923
B25: Policy Fees | C25: 1554 | D25: 2174 | E25: 1928 | F25: 1736 | G25: 2204 | H25: 2967 | I25: 2805 | J25: 2422 | K25: 2745 | V25: 7393 | W25: 10397
B26: Net Investment Income | C26: 3248 | D26: 3414 | E26: 3757 | F26: 3760 | G26: 4103 | H26: 4780 | I26: 6906 | J26: 5916 | K26: 5652 | V26: 14180 | W26: 21704
B27: Net Realized Gains on Investments | C27: 6 | D27: 78 | E27: 18 | F27: 16 | G27: 16 | H27: 485 | I27: 41 | J27: 27 | K27: 53 | V27: 119 | W27: 569
B28: Other Income | C28: 217 | D28: 198 | E28: 376 | F28: -183 | G28: 161 | H28: 98 | I28: 275 | J28: 358 | K28: 273 | V28: 607 | W28: 892
B29: Total Revenues | C29: =+SUM(C24:C28) -> 44308 | D29: =+SUM(D24:D28) -> 46383 | E29: =+SUM(E24:E28) -> 46543 | F29: =+SUM(F24:F28) -> 67118 | G29: =+SUM(G24:G28) -> 71886 | H29: =+SUM(H24:H28) -> 74499 | I29: =+SUM(I24:I28) -> 62026 | J29: =+SUM(J24:J28) -> 68075 | K29: =+SUM(K24:K28) -> 90931 | V29: =+SUM(V24:V28) -> 204354 | W29: =+SUM(W24:W28) -> 276485 | X29: =W29 -> 276485 | Y29: =X29 -> 276485 | Z29: =Y29 -> 276485 | AA29: =Z29 -> 276485 | AB29: =AA29 -> 276485 | AC29: =AB29 -> 276485 | AD29: =AC29 -> 276485 | AE29: =AD29 -> 276485 | ... AG29: =AF29 -> 276485
B30: Loss and Loss Adjustment Expenses | C30: 20365 | D30: 12642 | E30: 25017 | F30: 32808 | G30: 20862 | H30: 21189 | I30: 29652 | J30: 26332 | K30: 31725 | V30: 90832 | W30: 98034 | X30: =W30 -> 98034 | Y30: =X30 -> 98034 | Z30: =Y30 -> 98034 | AA30: =Z30 -> 98034 | AB30: =AA30 -> 98034 | AC30: =AB30 -> 98034 | AD30: =AC30 -> 98034 | AE30: =AD30 -> 98034 | ... AG30: =AF30 -> 98034
B31: Policy Acquisition | C31: 5354 | D31: 6551 | E31: 7790 | F31: 11837 | G31: 3107 | H31: 6281 | I31: 6254 | J31: 5804 | K31: 15985 | V31: 31532 | W31: 21446 | X31: =W31 -> 21446 | Y31: =X31 -> 21446 | Z31: =Y31 -> 21446 | AA31: =Z31 -> 21446 | AB31: =AA31 -> 21446 | AC31: =AB31 -> 21446 | AD31: =AC31 -> 21446 | AE31: =AD31 -> 21446 | ... AG31: =AF31 -> 21446
B32: G&A | C32: 5282 | D32: 6757 | E32: 7185 | F32: 11727 | G32: 5008 | H32: 22932 | I32: 7347 | J32: 6661 | K32: 15966 | V32: 30951 | W32: 41948 | X32: =W32 -> 41948 | Y32: =X32 -> 41948 | Z32: =Y32 -> 41948 | AA32: =Z32 -> 41948 | AB32: =AA32 -> 41948 | AC32: =AB32 -> 41948 | AD32: =AC32 -> 41948 | AE32: =AD32 -> 41948 | ... AG32: =AF32 -> 41948
B33: EBT | C33: =+C29-SUM(C30:C32) -> 13307 | D33: =+D29-SUM(D30:D32) -> 20433 | E33: =+E29-SUM(E30:E32) -> 6551 | F33: =+F29-SUM(F30:F32) -> 10746 | G33: =+G29-SUM(G30:G32) -> 42909 | H33: =+H29-SUM(H30:H32) -> 24097 | I33: =+I29-SUM(I30:I32) -> 18773 | J33: =+J29-SUM(J30:J32) -> 29278 | K33: =+K29-SUM(K30:K32) -> 27255 | V33: =+V29-SUM(V30:V32) -> 51039 | W33: =+W29-SUM(W30:W32) -> 115057 | X33: =W33 -> 115057 | Y33: =X33 -> 115057 | Z33: =Y33 -> 115057 | AA33: =Z33 -> 115057 | AB33: =AA33 -> 115057 | AC33: =AB33 -> 115057 | AD33: =AC33 -> 115057 | AE33: =AD33 -> 115057 | ... AG33: =AF33 -> 115057
B34: Taxes | C34: 1201 | D34: 5709 | E34: 2038 | F34: 2349 | G34: 4813 | H34: -3397 | I34: 5610 | J34: 8409 | K34: 7345 | V34: 11297 | W34: 15436 | X34: =W34 -> 15436 | Y34: =X34 -> 15436 | Z34: =Y34 -> 15436 | AA34: =Z34 -> 15436 | AB34: =AA34 -> 15436 | AC34: =AB34 -> 15436 | AD34: =AC34 -> 15436 | AE34: =AD34 -> 15436 | ... AG34: =AF34 -> 15436
B35: Net Earnings | C35: =+C33-C34 -> 12106 | D35: =+D33-D34 -> 14724 | E35: =+E33-E34 -> 4513 | F35: =+F33-F34 -> 8397 | G35: =+G33-G34 -> 38096 | H35: =+H33-H34 -> 27494 | I35: =+I33-I34 -> 13163 | J35: =+J33-J34 -> 20869 | K35: =+K33-K34 -> 19910 | V35: =+V33-V34 -> 39742 | W35: =+W33-W34 -> 99621 | X35: =W35 -> 99621 | Y35: =X35 -> 99621 | Z35: =Y35 -> 99621 | AA35: =Z35 -> 99621 | AB35: =AA35 -> 99621 | AC35: =AB35 -> 99621 | AD35: =AC35 -> 99621 | AE35: =AD35 -> 99621 | ... AG35: =AF35 -> 99621 | AH35: =+AG35*(1+$AJ$39) -> 98624.79 | AI35: =+AH35*(1+$AJ$39) -> 97638.542 | AJ35: =+AI35*(1+$AJ$39) -> 96662.157 | AK35: =+AJ35*(1+$AJ$39) -> 95695.535 | AL35: =+AK35*(1+$AJ$39) -> 94738.58 | AM35: =+AL35*(1+$AJ$39) -> 93791.194 | AN35: =+AM35*(1+$AJ$39) -> 92853.282 | AO35: =+AN35*(1+$AJ$39) -> 91924.749 | ... BA35: =+AZ35*(1+$AJ$39) -> 81480.707
B36: Diluted Shares | C36: 122900 | D36: 12904.495 | E36: 12904.495 | F36: 12904.495 | G36: 122900 | H36: 16962.075 | I36: 19572.595 | J36: 19577.036 | K36: 19579.308 | V36: 12904.495 | W36: 17235.376 | X36: =W36 -> 17235.376 | Y36: =X36 -> 17235.376 | Z36: =Y36 -> 17235.376 | AA36: =Z36 -> 17235.376 | AB36: =AA36 -> 17235.376 | AC36: =AB36 -> 17235.376 | AD36: =AC36 -> 17235.376 | AE36: =AD36 -> 17235.376 | ... AG36: =AF36 -> 17235.376
B37: EPS | C37: =+C35/C36 -> 0.098502848 | D37: =+D35/D36 -> 1.1409978 | E37: =+E35/E36 -> 0.3497231 | F37: =+F35/F36 -> 0.6507035 | G37: =+G35/G36 -> 0.30997559 | H37: =+H35/H36 -> 1.6209102 | I37: =+I35/I36 -> 0.67252196 | J37: =+J35/J36 -> 1.0659939 | K37: =+K35/K36 -> 1.0168899 | V37: =+V35/V36 -> 3.0797021 | W37: =+W35/W36 -> 5.7800306 | X37: =W37 -> 5.7800306 | Y37: =X37 -> 5.7800306 | Z37: =Y37 -> 5.7800306 | AA37: =Z37 -> 5.7800306 | AB37: =AA37 -> 5.7800306 | AC37: =AB37 -> 5.7800306 | AD37: =AC37 -> 5.7800306 | AE37: =AD37 -> 5.7800306 | ... AG37: =AF37 -> 5.7800306
B39: Growth Y/Y | V39: =+V34/V33 -> 0.22134054 | W39: =+W34/W33 -> 0.13415959 | X39: =+X34/X33 -> 0.13415959 | Y39: =+Y34/Y33 -> 0.13415959 | Z39: =+Z34/Z33 -> 0.13415959 | AA39: =+AA34/AA33 -> 0.13415959 | AB39: =+AB34/AB33 -> 0.13415959 | AC39: =+AC34/AC33 -> 0.13415959 | ... AG39: =+AG34/AG33 -> 0.13415959 | AI39: Maturity | AJ39: -0.01
B40: Total Revenues | G40: =+G29/C29-1 -> 0.62241582 | H40: =+H29/D29-1 -> 0.60617036 | I40: =+I29/E29-1 -> 0.33266012 | J40: =+J29/F29-1 -> 0.01425847 | K40: =+K29/G29-1 -> 0.26493337
B41: Gross Premiums Written | G41: =+G20/C20-1 -> 0.4387733 | H41: =+H20/D20-1 -> 0.2949168 | I41: =+I20/E20-1 -> 0.48530535 | J41: =+J20/F20-1 -> -0.13142578 | K41: =+K20/G20-1 -> 0.037020976 | W41: =+W20/V20-1 -> 0.2305081 | AI41: Discount | AJ41: 0.15 | AK41: 0.16 | AL41: 0.17 | AM41: 0.18
B42: Gross Premiums Earned | G42: =+G22/C22-1 -> 0.3391874 | H42: =+H22/D22-1 -> 0.39762378 | I42: =+I22/E22-1 -> 0.34220886 | J42: =+J22/F22-1 -> 0.14647144 | K42: =+K22/G22-1 -> 0.098098555 | W42: =+W22/V22-1 -> 0.29718154 | AI42: NPV | AJ42: =NPV(AJ41,Model!$X$35:$FO$35) -> 644726.24 | AK42: =NPV(AK41,Model!$X$35:$FO$35) -> 607473.35 | AL42: =NPV(AL41,Model!$X$35:$FO$35) -> 574046.68 | AM42: =NPV(AM41,Model!$X$35:$FO$35) -> 543921.44
B43: Net Premiums Earned | G43: =+G24/C24-1 -> 0.66489321 | H43: =+H24/D24-1 -> 0.63303635 | I43: =+I24/E24-1 -> 0.28506821 | J43: =+J24/F24-1 -> -0.039440677 | K43: =+K24/G24-1 -> 0.25696462 | W43: =+W24/V24-1 -> 0.33433852 | X43: =+X24/W24-1 -> -1 | Y43: =+Y24/X24-1 -> #DIV/0! | Z43: =+Z24/Y24-1 -> #DIV/0! | AA43: =+AA24/Z24-1 -> #DIV/0! | AB43: =+AB24/AA24-1 -> #DIV/0! | AC43: =+AC24/AB24-1 -> #DIV/0! | AD43: =+AD24/AC24-1 -> #DIV/0! | ... AG43: =+AG24/AF24-1 -> #DIV/0! | AI43: Shares | AJ43: =+Main!K5 * 1000 -> 19590.817
C44: =+C33/C29 -> 0.30032951 | D44: =+D33/D29 -> 0.44052778 | E44: =+E33/E29 -> 0.14075156 | F44: =+F33/F29 -> 0.16010608 | G44: =+G33/G29 -> 0.59690343 | H44: =+H33/H29 -> 0.32345401 | I44: =+I33/I29 -> 0.3026634 | J44: =+J33/J29 -> 0.43008447 | K44: =+K33/K29 -> 0.29973276 | V44: =+V33/V29 -> 0.24975777 | W44: =+W33/W29 -> 0.41614192 | X44: =+X33/X29 -> 0.41614192 | Y44: =+Y33/Y29 -> 0.41614192 | Z44: =+Z33/Z29 -> 0.41614192 | AA44: =+AA33/AA29 -> 0.41614192 | AB44: =+AB33/AB29 -> 0.41614192 | AC44: =+AC33/AC29 -> 0.41614192 | ... AG44: =+AG33/AG29 -> 0.41614192 | AI44: Estimate | AJ44: =+AJ42/AJ43 -> 32.909615 | AK44: =+AK42/$AJ$43 -> 31.008066 | AL44: =+AL42/$AJ$43 -> 29.301824 | AM44: =+AM42/$AJ$43 -> 27.764102
B45: Diluted Shares | G45: =+G36/C36-1 -> 0 | H45: =+H36/D36-1 -> 0.31443152 | I45: =+I36/E36-1 -> 0.51672692 | J45: =+J36/F36-1 -> 0.51707107 | K45: =+K36/G36-1 -> -0.84068911 | V45: =+V32/V29 -> 0.15145776 | W45: =+W32/W29 -> 0.1517189 | AI45: Current | AJ45: =+Main!K4 -> 16.6
...
