Workbook

Sheet Main
B1: IR
B3: HQ: Denver, CO
B4: CEO | C4: Tom Palmer | J4: P | K4: 105 | N4: News | O4: Contains
B5: New CEO | C5: Natascha Viljoen's | J5: S | K5: 1091.263 | L5: Q325 | N5: 45632 | O5: selling Cripple Creek & Victor operation in Colorado to SSR Mining for up to $275m
B6: CFO | J6: MC | K6: =+K4*K5 -> 114582.61 | N6: 45621 | O6: selling Eleonore operation in Northern Quebec
J7: C | K7: =5639+4103 -> 9742 | L7: =+L5 -> Q325 | N7: 45614 | O7: selling Musselwhite operation in Ontario, Canada
B8: P * Q | J8: D | K8: 5180 | L8: =+L7 -> Q325 | N8: 45594 | O8: 1st battery ev large mining truck deployed in cripple creek colorado
B9: P: LBMA (Gold),LME (Cu), Timing | J9: EV | K9: =+K6-K7+K8 -> 110020.61 | N9: 45573 | O9: selling Akyem operation in Repub of Ghana to Zijin Mining Group
B10: Q: Production capability (mine capacity, mill throughput, weather), recovery (metallurgy/cil/heap effic, Ownership) | N10: 45568 | O10: announces Tom palmer as Internal council on Mining and Metald) ICMM chair
N11: 45588 | O11: Q4 guidance: 1.8m oz of gold
B12: Equity Method Investments | N12: 45497 | O12: annual prod guide: 6.9m oz
B13: Pueblo Viejo Mine (50%) | N13: 45407 | O13: reaffirmed guide
B14: NuevaUnion Project (50%)
B15: Lundin Gold (32%)
B16: Norte Abierto Project (50%) | N16: Press Releases
B17: Greatland (10%) | N17: 45953 | O17: Q325 results
N18: 45770 | O18: Q125 Results
N19: 45684 | O19: early redemption of 5.3% notes due 2026
N20: 45684 | O20: sale of porcupine operation for up $425m

Sheet Model
C2: Q122 | D2: Q222 | E2: Q322 | F2: Q422 | G2: Q123 | H2: Q223 | I2: Q323 | J2: Q423 | K2: Q124 | L2: Q224 | M2: Q324 | N2: Q424 | O2: Q125 | P2: Q225 | Q2: Q325 | R2: Q425 | W2: 2015 | X2: =+W2+1 -> 2016 | Y2: =+X2+1 -> 2017 | Z2: =+Y2+1 -> 2018 | AA2: 2019 | AB2: 2020 | AC2: 2021 | AD2: 2022 | AE2: 2023 | AF2: =+AE2+1 -> 2024 | AG2: =+AF2+1 -> 2025 | AH2: =+AG2+1 -> 2026 | AI2: =+AH2+1 -> 2027 | AJ2: =+AI2+1 -> 2028 | AK2: =+AJ2+1 -> 2029 | AL2: =+AK2+1 -> 2030 | AM2: =+AL2+1 -> 2031 | ... IG2: =+IF2+1 -> 2233
B3: LBMA Gold Price
B4: Low | W4: 1049 | X4: 1077 | Y4: 1151 | Z4: 1178 | AA4: 1270 | AB4: 1474 | AC4: 1684 | AD4: 1629 | AE4: 1811 | AF4: 1985 | AG4: 2636
B5: High | W5: 1296 | X5: 166 | Y5: 1346 | Z5: 1355 | AA5: 1546 | AB5: 2067 | AC5: 1943 | AD5: 2039 | AE5: 2078 | AF5: 2778 | AG5: 2928
B6: Mean | W6: 1160 | X6: 1251 | Y6: 1257 | Z6: 1268 | AA6: 1393 | AB6: 1770 | AC6: 1799 | AD6: 1800 | AE6: 1941 | AF6: 2386 | AG6: 2759
B7: Portfolio
B8: Boddington | K8: 142 | L8: 147 | M8: 137 | N8: 164 | O8: 126 | P8: 147 | Q8: 146 | AF8: =SUM(K8:N8) -> 590 | AG8: =SUM(O8:R8) -> 419
B9: Tanami | K9: 90 | L9: 99 | M9: 102 | N9: 117 | O9: 78 | P9: 90 | Q9: 100 | AF9: =SUM(K9:N9) -> 408 | AG9: =SUM(O9:R9) -> 268
B10: Cadia | K10: 122 | L10: 117 | M10: 115 | N10: 110 | O10: 103 | P10: 104 | Q10: 97 | AF10: =SUM(K10:N10) -> 464 | AG10: =SUM(O10:R10) -> 304
B11: Likir | K11: 181 | L11: 141 | M11: 129 | N11: 163 | O11: 164 | P11: 160 | Q11: 129 | AF11: =SUM(K11:N11) -> 614 | AG11: =SUM(O11:R11) -> 453
B12: Ahafo | K12: 190 | L12: 184 | M12: 213 | N12: 211 | O12: 205 | P12: 197 | Q12: 145 | AF12: =SUM(K12:N12) -> 798 | AG12: =SUM(O12:R12) -> 547
B13: Ahafo North | AF13: =SUM(K13:N13) -> 0 | AG13: =SUM(O13:R13) -> 0
B14: Penasquito | K14: 45 | L14: 64 | M14: 63 | N14: 127 | O14: 123 | P14: 148 | Q14: 88 | AF14: =SUM(K14:N14) -> 299 | AG14: =SUM(O14:R14) -> 359
B15: Cerro Negro | K15: 81 | L15: 19 | M15: 60 | N15: 78 | O15: 28 | P15: 42 | Q15: 68 | AF15: =SUM(K15:N15) -> 238 | AG15: =SUM(O15:R15) -> 138
B16: Yanacocha | K16: 91 | L16: 78 | M16: 93 | N16: 92 | O16: 105 | P16: 131 | Q16: 152 | AF16: =SUM(K16:N16) -> 354 | AG16: =SUM(O16:R16) -> 388
B17: Merian | K17: 57 | L17: 46 | M17: 43 | N17: 59 | O17: 47 | P17: 40 | Q17: 35 | AF17: =SUM(K17:N17) -> 205 | AG17: =SUM(O17:R17) -> 122
B18: Nrucejack | K18: 37 | L18: 60 | M18: 89 | N18: 72 | O18: 41 | P18: 50 | Q18: 79 | AF18: =SUM(K18:N18) -> 258 | AG18: =SUM(O18:R18) -> 170
B19: Red Chris | K19: 6 | L19: 9 | M19: 9 | N19: 16 | O19: 14 | P19: 15 | Q19: 15 | AF19: =SUM(K19:N19) -> 40 | AG19: =SUM(O19:R19) -> 44
B20: Nevada Gold Mines (38.5%) | K20: 264 | L20: 253 | M20: 242 | N20: 280 | O20: 216 | P20: 239 | Q20: 251 | AF20: =SUM(K20:N20) -> 1039 | AG20: =SUM(O20:R20) -> 706
B21: Oueblo Viejo (40%) | K21: 54 | L21: 53 | M21: 66 | N21: 62 | O21: 49 | P21: 63 | Q21: 72 | AF21: =SUM(K21:N21) -> 235 | AG21: =SUM(O21:R21) -> 184
B22: Fruta Del Norte (32%) | K22: 21 | L22: 35 | M22: 43 | N22: 39 | O22: 43 | P22: 38 | Q22: 44 | AF22: =SUM(K22:N22) -> 138 | AG22: =SUM(O22:R22) -> 125
B23: Total Tier 1 Portfolio Production | K23: =SUM(K8:K19,K20:K22) -> 1381 | L23: =SUM(L8:L19,L20:L22) -> 1305 | M23: =SUM(M8:M19,M20:M22) -> 1404 | N23: =SUM(N8:N19,N20:N22) -> 1590 | O23: =SUM(O8:O19,O20:O22) -> 1342 | P23: =SUM(P8:P19,P20:P22) -> 1464 | Q23: =SUM(Q8:Q19,Q20:Q22) -> 1421 | AF23: =SUM(K23:N23) -> 5680 | AG23: =SUM(O23:R23) -> 4227
B24: Non Core Assets | K24: 294 | L24: 302 | M24: 264 | N24: 309 | O24: 195 | P24: 14 | Q24: 0 | AF24: =SUM(K24:N24) -> 1169 | AG24: =SUM(O24:R24) -> 209
B25: Total Attributable Gold Production | K25: =SUM(K23:K24) -> 1675 | L25: =SUM(L23:L24) -> 1607 | M25: =SUM(M23:M24) -> 1668 | N25: =SUM(N23:N24) -> 1899 | O25: =SUM(O23:O24) -> 1537 | P25: =SUM(P23:P24) -> 1478 | Q25: =SUM(Q23:Q24) -> 1421 | AD25: 5956 | AE25: 5554 | AF25: =SUM(K25:N25) -> 6849 | AG25: =SUM(O25:R25) -> 4436
B27: Metal Sold
B28: Gold Oz Sold (koz) | G28: 1188 | H28: 1197 | I28: 1229 | J28: 1726 | K28: 1599 | L28: 1543 | M28: 1568 | N28: =+AF28-SUM(K28:M28) -> 1829 | O28: 1442 | P28: 1380 | Q28: 1319 | R28: 1600 | AD28: 5812 | AE28: 5420 | AF28: 6539 | AG28: =+AF28*1.05 -> 6865.95 | AH28: 6800 | AI28: 6800 | AJ28: 6800 | AK28: 6800 | AL28: 6800 | AM28: 6800 | AN28: 6800 | AO28: 6800 | AP28: 6800
B29: Copper Sold ($/lb) | K29: 80 | L29: 84 | M29: 77 | N29: =+AF29-SUM(K29:M29) -> 91 | O29: 76 | P29: 83 | Q29: 68 | R29: =+Q29*1.05 -> 71.4 | AD29: 85 | AE29: 155 | AF29: 332 | AG29: =+AF29*1.05 -> 348.6 | AH29: 400 | AI29: 400 | AJ29: 400 | AK29: 400 | AL29: 400 | AM29: 400 | AN29: 400 | AO29: 400 | AP29: 400
B30: Silver ($/moz) | K30: 10 | L30: 8 | M30: 6 | N30: =+AF30-SUM(K30:M30) -> 9 | O30: 6 | P30: 7 | Q30: 8 | R30: =+Q30*1.05 -> 8.4 | AD30: 30 | AE30: 17 | AF30: 33 | AG30: =+AF30*1.05 -> 34.65 | AH30: 40 | AI30: 40 | AJ30: 40 | AK30: 40 | AL30: 40 | AM30: 40 | AN30: 40 | AO30: 40 | AP30: 40
B31: Lead ($/lb) | K31: 65 | L31: 43 | M31: 36 | N31: =+AF31-SUM(K31:M31) -> 69 | O31: 47 | P31: 50 | Q31: 60 | R31: =+Q31*1.05 -> 63 | AD31: 147 | AE31: 107 | AF31: 213 | AG31: =+AF31*1.05 -> 223.65 | AH31: 200 | AI31: 200 | AJ31: 200 | AK31: 200 | AL31: 200 | AM31: 200 | AN31: 200 | AO31: 200 | AP31: 200
B32: Zinc ($/lb) | K32: 135 | L32: 113 | M32: 134 | N32: =+AF32-SUM(K32:M32) -> 163 | O32: 161 | P32: 124 | Q32: 149 | R32: =+Q32*1.05 -> 156.45 | AD32: 373 | AE32: 222 | AF32: 545 | AG32: =+AF32*1.05 -> 572.25 | AH32: 600 | AI32: 600 | AJ32: 600 | AK32: 600 | AL32: 600 | AM32: 600 | AN32: 600 | AO32: 600 | AP32: 600
B33: Average Realized Price | R33: 4325
B34: Gold ($/oz) | G34: 1906 | H34: 1965 | I34: 1920 | J34: 2004 | K34: 2090 | L34: 2347 | M34: 2518 | N34: 2643 | O34: 2944 | P34: 3320 | Q34: 3539 | R34: =+Q34 -> 3539 | AE34: 1954 | AF34: =+N34 -> 2643 | AG34: =+R34 -> 3539 | AH34: =+AG34*1.05 -> 3715.95 | AI34: =+AH34*1.05 -> 3901.7475 | AJ34: =+'Key Questions'!C16 -> 4341.0498 | AK34: =+AJ34 -> 4341.0498 | AL34: =+AK34 -> 4341.0498 | AM34: =+AL34 -> 4341.0498 | AN34: =+AM34 -> 4341.0498 | AO34: =+AN34 -> 4341.0498 | AP34: =+AO34 -> 4341.0498
B35: Copper ($/lb) | K35: 3.72 | L35: 4.47 | M35: 4.31 | N35: 3.57 | O35: 4.65 | P35: 4.37 | Q35: 4.67 | R35: =AVERAGE(O35:Q35) -> 4.5633333 | AF35: =+N35 -> 3.57 | AG35: =+R35 -> 4.5633333 | AH35: =+AG35*1.05 -> 4.7915 | AI35: =+AH35*1.05 -> 5.031075 | AJ35: =+AI35*1.05 -> 5.2826288 | AK35: =+AJ35*1.05 -> 5.5467602 | AL35: =+AK35*1.05 -> 5.8240982 | AM35: =+AL35 -> 5.8240982 | AN35: =+AM35 -> 5.8240982 | AO35: =+AN35 -> 5.8240982 | AP35: =+AO35 -> 5.8240982
B36: Silver ($/moz) | K36: 20.41 | L36: 26.2 | M36: 25.98 | N36: 25.15 | O36: 30.12 | P36: 29.5 | Q36: 37.02 | R36: =AVERAGE(O36:Q36) -> 32.213333 | AF36: =+N36 -> 25.15 | AG36: =+R36 -> 32.213333 | AH36: =+AG36*1.05 -> 33.824 | AI36: =+AH36*1.05 -> 35.5152 | AJ36: =+AI36*1.05 -> 37.29096 | AK36: =+AJ36*1.05 -> 39.155508 | AL36: =+AK36*1.05 -> 41.113283 | AM36: =+AL36 -> 41.113283 | AN36: =+AM36 -> 41.113283 | AO36: =+AN36 -> 41.113283 | AP36: =+AO36 -> 41.113283
B37: Lead ($/lb) | K37: 0.92 | L37: 1.05 | M37: 0.86 | N37: 0.86 | O37: 0.89 | P37: 0.88 | Q37: 0.86 | R37: =AVERAGE(O37:Q37) -> 0.87666667 | AF37: =+N37 -> 0.86 | AG37: =+R37 -> 0.87666667 | AH37: =+AG37*1.05 -> 0.9205 | AI37: =+AH37*1.05 -> 0.966525 | AJ37: =+AI37*1.05 -> 1.0148513 | AK37: =+AJ37*1.05 -> 1.0655938 | AL37: =+AK37*1.05 -> 1.1188735 | AM37: =+AL37 -> 1.1188735 | AN37: =+AM37 -> 1.1188735 | AO37: =+AN37 -> 1.1188735 | AP37: =+AO37 -> 1.1188735
B38: Zinc ($/lb) | K38: 0.92 | L38: 1.31 | M38: 1.14 | N38: 1.21 | O38: 1.13 | P38: 1.13 | Q38: 1.29 | R38: =AVERAGE(O38:Q38) -> 1.1833333 | AF38: =+N38 -> 1.21 | AG38: =+R38 -> 1.1833333 | AH38: =+AG38*1.05 -> 1.2425 | AI38: =+AH38*1.05 -> 1.304625 | AJ38: =+AI38*1.05 -> 1.3698563 | AK38: =+AJ38*1.05 -> 1.4383491 | AL38: =+AK38*1.05 -> 1.5102665 | AM38: =+AL38 -> 1.5102665 | AN38: =+AM38 -> 1.5102665 | AO38: =+AN38 -> 1.5102665 | AP38: =+AO38 -> 1.5102665
B40: Gold CAS ($/oz) | K40: 1057 | L40: 1152 | M40: 1207 | N40: 1096 | O40: 1227 | P40: 1215 | Q40: 1815 | AF40: 1126
B41: Gold AISC ($/oz) | K41: 1439 | L41: 1562 | M41: 1611 | N41: 1463 | O41: 1651 | P41: 1593 | Q41: 1566 | AF41: 1516
B43: Modeled Revenue
B44: Gold | L44: =+L28*L34/10^3 -> 3621.421 | M44: =+M28*M34/10^3 -> 3948.224 | O44: =+O28*O34/10^3 -> 4245.248 | P44: =+P28*P34/10^3 -> 4581.6 | Q44: =+Q28*Q34/10^3 -> 4667.941 | R44: =+R28*R34/10^3 -> 5662.4 | AG44: =SUM(O44:R44) -> 19157.189 | AH44: =+AH28*AH34/10^3 -> 25268.46 | AI44: =+AI28*AI34/10^3 -> 26531.883 | AJ44: =+AJ28*AJ34/10^3 -> 29519.139 | AK44: =+AK28*AK34/10^3 -> 29519.139 | AL44: =+AL28*AL34/10^3 -> 29519.139 | AM44: =+AM28*AM34/10^3 -> 29519.139 | AN44: =+AN28*AN34/10^3 -> 29519.139 | AO44: =+AO28*AO34/10^3 -> 29519.139 | AP44: =+AP28*AP34/10^3 -> 29519.139
...

Sheet Definitions
B3: Unit | C3: Unit of Measure
B4: $ | C4: United States Dollar
B5: % | C5: Percent
B6: A$ | C6: Australian Dollar
B7: C$ | C7: Canadian Dollar
B8: gram | C8: Metric Gram
B9: ounce | C9: Troy Ounce
B10: pound | C10: United States Pound
B11: tonne | C11: Metric Ton
B12: Abbreviation | C12: Description
B13: AISC (1) | C13: All-In Sustaining Costs
B14: ARC | C14: Asset Retirement Cost
... B59: Heap Leaching | C59: Used when ore is low grade. Process. (1) Ore is crushed.

Sheet Key Questions
B2: $M
B5: What gold price is implicitly required to justify current market cap at a mid cycle multiple?
B6: Model | D6: Notes
B7: MC | C7: =+Main!K6 -> 114582.61
B8: Net Cash | C8: =+Main!K7-Main!K8 -> 4562
B9: EV | C9: =+C7-C8 -> 110020.61
B10: Needed FCF | C10: =+C9/7 -> 15717.23 | D10: assumes ~7x fcf
B11: FY25 Gold Sold | C11: =SUM(Model!O28:R28) -> 5741
B12: Sustaining AISC | C12: =AVERAGE(1651,1593,1566) -> 1603.3333
B14: FCF Per Oz Needed | C14: =+(C10/C11) * 1000 -> 2737.7165
B15: Gold price - $1.603/oz = $2,854/oz
B16: Required Gold Price | C16: =+C12+C14 -> 4341.0498 | D16: If gold can stay above $4,000, business will naturally strengthen
B18: Average of current realized Godl Prices | C18: =AVERAGE(Model!O34:R34) -> 3335.5
B19: Current LBMA Price | C19: 4251.7 | D19: 46010
B20: Revenue Price Lag | C20: =+C19-C18 -> 916.2
B22: Incremental Rev | C22: =+(C11*C20) / 10^3 -> 5259.9042
B23: Incremental Margin | C23: 0.75
B24: After tax Conversion | C24: 0.7
B25: Incremental FCF | C25: =+C22*C23*C24 -> 2761.4497
B27: Adjusted FCF | C27: =+SUM(Model!Q140,'Key Questions'!C25) -> 8883.4497 | D27: overtime 4Q FCF should approach thise as Godl stays around $4k/oz
B28: Capex Normalization (Post Buildouts) | C28: 1500

Sheet Geology
B2: Reading Material
B3: Reserves and Resources
B4: 2024
B5: =+B4-1 -> 2023
B6: =+B5-1 -> 2022
B7: =+B6-1 -> 2021
B8: =+B7-1 -> 2020
B9: =+B8-1 -> 2019
B10: =+B9-1 -> 2018
B11: =+B10-1 -> 2017
B12: =+B11-1 -> 2016
B13: =+B12-1 -> 2015
B16: Lifecycle of a Mine
B17: Mining Process
B18: What we Mine

Sheet Operations
B9: Africa Asia Pacific
B10: Africa
B11: Ahafo North, Ghana
B12: Ahafo South, Ghana
B13: Australia
B14: Boddington, Australia
B15: Cadia, Australia
B16: Tanami, Australia
B17: Papua New Guinea
B18: Lihir, Papua New Guinea
B19: Americas
B20: Canada
... B32: Health and Safety
