Workbook

Sheet Miain
A1: $m | G1: =+G5/G14 -> 0.65018862 | H1: =+H5/H14 -> 0.63453596 | I1: =+I5/I14 -> 0.55179163 | J1: =+J5/J14 -> 0.56220196 | K1: =+K5/K14 -> 0.60227362 | L1: =+L5/L14 -> 0.61210047 | M1: =+M5/M14 -> 0.62513733 | N1: =+N5/N14 -> 0.5991663 | O1: =+O5/O14 -> 0.59406148
G2: =+G6/G14 -> 0.30084879 | H2: =+H6/H14 -> 0.29650121 | I2: =+I6/I14 -> 0.2521078 | J2: =+J6/J14 -> 0.23751753 | K2: =+K6/K14 -> 0.32572827 | L2: =+L6/L14 -> 0.30632242 | M2: =+M6/M14 -> 0.30154545 | N2: =+N6/N14 -> 0.34642387 | O2: 0.3
D3: 45108 | F3: 45290 | H3: 45472 | I3: 45563 | K3: 45741 | L3: 45836 | AQ3: AI slowdown | AZ3: 1 | BA3: =+AZ3+1 -> 2 | BB3: =+BA3+1 -> 3 | BC3: =+BB3+1 -> 4 | BD3: =+BC3+1 -> 5 | BE3: =+BD3+1 -> 6 | BF3: =+BE3+1 -> 7 | BG3: =+BF3+1 -> 8 | BH3: =+BG3+1 -> 9 | ... IQ3: =+IP3+1 -> 200
C4: Q123 | D4: Q223 | E4: Q323 | F4: Q423 | G4: Q124 | H4: Q224 | I4: Q324 | J4: Q424 | K4: Q125 | L4: Q225 | M4: Q325 | N4: Q425 | O4: Q126 | P4: Q226 | Q4: Q326 | R4: Q426 | W4: 2007 | X4: =+W4+1 -> 2008 | Y4: =+X4+1 -> 2009 | Z4: =+Y4+1 -> 2010 | AA4: =+Z4+1 -> 2011 | AB4: =+AA4+1 -> 2012 | AC4: =+AB4+1 -> 2013 | AD4: =+AC4+1 -> 2014 | AE4: =+AD4+1 -> 2015 | ... IQ4: =+IP4+1 -> 2235
B5: CCG | C5: 5767 | D5: 6780 | E5: 7867 | F5: 8844 | G5: 8273 | H5: 8143 | I5: 7330 | J5: 8017 | K5: 7629 | L5: 7871 | M5: 8535 | N5: 8193 | O5: =+K5*0.95 -> 7247.55 | P5: =+L5*1.05 -> 8264.55 | AI5: 37146 | AJ5: 40057 | AK5: 41067 | AL5: 31708 | AM5: =SUM(C5:F5) -> 29258 | AN5: =SUM(G5:J5) -> 31763 | AO5: =SUM(K5:N5) -> 32228 | AP5: =+AO5*1.05 -> 33839.4 | AQ5: =+AP5*1.02 -> 34516.188 | AR5: =+AQ5*1.02 -> 35206.512 | AS5: =+AR5*1.04 -> 36614.772 | AT5: =+AS5*1.04 -> 38079.363 | AU5: =+AT5*1.04 -> 39602.538 | AV5: =+AU5*1.04 -> 41186.639 | AW5: =+AV5*1.04 -> 42834.105 | AX5: =+AW5*1.04 -> 44547.469 | AY5: =+AX5*1.04 -> 46329.368
B6: DCAI | C6: 2901 | D6: 3155 | E6: 3076 | F6: 3503 | G6: 3828 | H6: 3805 | I6: 3349 | J6: 3387 | K6: 4126 | L6: 3939 | M6: 4117 | N6: 4737 | O6: =+O14*0.33 -> 4026 | AI6: 23481 | AJ6: 26103 | AK6: 22691 | AL6: 19196 | AM6: =SUM(C6:F6) -> 12635 | AN6: =SUM(G6:J6) -> 14369 | AO6: =SUM(K6:N6) -> 16919 | AP6: =+AO6*1.05 -> 17764.95 | AQ6: =+AP6*1.01 -> 17942.6 | AR6: =+AQ6*1.01 -> 18122.025 | AS6: =+AR6*1.05 -> 19028.127 | AT6: =+AS6*1.05 -> 19979.533 | AU6: =+AT6*1.05 -> 20978.51 | AV6: =+AU6*1.05 -> 22027.435 | AW6: =+AV6*1.05 -> 23128.807 | AX6: =+AW6*1.05 -> 24285.247 | AY6: =+AX6*1.05 -> 25499.51
B7: Network/Edge | C7: 1489 | D7: 1364 | E7: 1450 | F7: 1471 | I7: 1511 | J7: 1623 | AK7: 7976 | AL7: 8873 | AM7: =SUM(C7:F7) -> 5774 | AN7: =SUM(G7:J7) -> 3134 | AO7: =SUM(K7:N7) -> 0
B8: Total Intel Products | C8: =SUM(C5:C7) -> 10157 | D8: =SUM(D5:D7) -> 11299 | E8: =SUM(E5:E7) -> 12393 | F8: =SUM(F5:F7) -> 13818 | G8: =SUM(G5:G7) -> 12101 | H8: =SUM(H5:H7) -> 11948 | I8: =SUM(I5:I7) -> 12190 | J8: =SUM(J5:J7) -> 13027 | ... O8: =SUM(O5:O7) -> 11273.55 | AK8: =SUM(AK5:AK7) -> 71734 | AL8: =SUM(AL5:AL7) -> 59777 | AM8: =SUM(C8:F8) -> 47667 | AN8: =SUM(G8:J8) -> 49266 | AO8: =SUM(K8:N8) -> 49147 | AP8: =SUM(AP5:AP7) -> 51604.35 | AQ8: =SUM(AQ5:AQ7) -> 52458.788 | AR8: =SUM(AR5:AR7) -> 53328.537 | AS8: =SUM(AS5:AS7) -> 55642.899 | AT8: =SUM(AT5:AT7) -> 58058.896 | AU8: =SUM(AU5:AU7) -> 60581.047 | AV8: =SUM(AV5:AV7) -> 63214.074 | AW8: =SUM(AW5:AW7) -> 65962.912 | ... AY8: =SUM(AY5:AY7) -> 71828.877
B9: Mobileye | AK9: 1386 | AL9: 1869
B10: Accelerated compsys | AK10: 774 | AL10: 837
B11: Intel Foundry | C11: 4831 | D11: 4172 | E11: 4732 | F11: 5175 | G11: 4356 | H11: 4282 | I11: 4352 | J11: 4502 | K11: 4667 | L11: 4417 | M11: 4235 | N11: 4507 | O11: =+O$14*(K11/K$14) -> 4494.9396 | AK11: 786 | AL11: 895 | AM11: =SUM(C11:F11) -> 18910 | AN11: =SUM(G11:J11) -> 17492 | AO11: =SUM(K11:N11) -> 17826 | AP11: =+AO11*1.03 -> 18360.78 | AQ11: =+AP11*1.03 -> 18911.603 | AR11: =+AQ11*1.03 -> 19478.952 | AS11: =+AR11*1.4 -> 27270.532 | AT11: =+AS11*1.1 -> 29997.585 | AU11: =+AT11*1.1 -> 32997.344 | AV11: =+AU11*1.1 -> 36297.078 | AW11: =+AV11*1.1 -> 39926.786 | AX11: =+AW11*1.1 -> 43919.465 | AY11: =+AX11*1.1 -> 48311.411
B12: All Other | C12: 1440 | D12: 1419 | E12: 1452 | F12: 1297 | G12: 643 | H12: 881 | I12: 1039 | J12: 1042 | K12: 943 | L12: 1053 | M12: 993 | N12: 574 | O12: =+O$14*(K12/K$14) -> 908.23399 | AK12: 5019 | AL12: 196 | AM12: =SUM(C12:F12) -> 5608 | AN12: =SUM(G12:J12) -> 3605 | AO12: =SUM(K12:N12) -> 3563 | AP12: =+AO12*1.01 -> 3598.63 | AQ12: =+AP12*1.01 -> 3634.6163 | AR12: =+AQ12*1.01 -> 3670.9625 | AS12: =+AR12*1.01 -> 3707.6721 | AT12: =+AS12*1.01 -> 3744.7488 | AU12: =+AT12*1.01 -> 3782.1963 | AV12: =+AU12*1.01 -> 3820.0183 | AW12: =+AV12*1.01 -> 3858.2184 | ... AY12: =+AX12*1.01 -> 3935.7686
B13: Interseg Elim | C13: -4713 | D13: -3941 | E13: -4419 | F13: -4884 | G13: -4376 | H13: -4278 | I13: -4297 | J13: -4311 | K13: -4698 | L13: -4421 | M13: -4227 | N13: -4337 | O13: =+O14-SUM(O8:O12) -> -4476.7236 | AM13: =SUM(C13:F13) -> -17957 | AN13: =SUM(G13:J13) -> -17262 | AO13: =SUM(K13:N13) -> -17683 | AP13: =+AO13 -> -17683 | AQ13: =+AP13 -> -17683 | AR13: =+AQ13 -> -17683 | AS13: =+AR13 -> -17683 | AT13: =+AS13 -> -17683 | AU13: =+AT13 -> -17683 | AV13: =+AU13 -> -17683 | AW13: =+AV13 -> -17683 | ... AY13: =+AX13 -> -17683
B14: Revenue | C14: =+SUM(C8:C13) -> 11715 | D14: =+SUM(D8:D13) -> 12949 | E14: =+SUM(E8:E13) -> 14158 | F14: =+SUM(F8:F13) -> 15406 | G14: =+SUM(G8:G13) -> 12724 | H14: =+SUM(H8:H13) -> 12833 | I14: =+SUM(I8:I13) -> 13284 | J14: =+SUM(J8:J13) -> 14260 | ... N14: =+SUM(N8:N13) -> 13674 | O14: =AVERAGE(11.7,12.7) * 10^3 -> 12200 | W14: 38334 | X14: 37586 | Y14: 35127 | Z14: 43623 | AA14: 53999 | AB14: 53341 | AC14: 52708 | AD14: 55870 | AE14: 55355 | AF14: 59387 | AG14: 62761 | AH14: 70848 | AI14: 71965 | AJ14: 77867 | AK14: =+SUM(AK8:AK13) -> 79699 | AL14: =+SUM(AL8:AL13) -> 63574 | AM14: =SUM(C14:F14) -> 54228 | AN14: =SUM(G14:J14) -> 53101 | AO14: =SUM(K14:N14) -> 52853 | AP14: =SUM(AP8:AP13) -> 55880.76 | AQ14: =SUM(AQ8:AQ13) -> 57322.007 | AR14: =SUM(AR8:AR13) -> 58795.451 | AS14: =SUM(AS8:AS13) -> 68938.103 | AT14: =SUM(AT8:AT13) -> 74118.23 | AU14: =SUM(AU8:AU13) -> 79677.588 | AV14: =SUM(AV8:AV13) -> 85648.171 | AW14: =SUM(AW8:AW13) -> 92064.916 | ... AY14: =SUM(AY8:AY13) -> 106393.06
B15: CoS | C15: 7707 | D15: 8311 | E15: 8140 | F15: 8359 | G15: 7507 | H15: 8286 | I15: 11287 | J15: 8676 | K15: 7995 | L15: 9317 | M15: 8435 | N15: =+AO15-SUM(K15:M15) -> 8731 | W15: 18430 | X15: 16742 | Y15: 15566 | Z15: 15132 | AA15: 20242 | AB15: 20190 | AC15: 21187 | AD15: 20261 | AE15: 20676 | AF15: 23154 | AG15: 23663 | AH15: 27111 | AI15: 29825 | AJ15: 34255 | AK15: 35209 | AL15: 36188 | AM15: =SUM(C15:F15) -> 32517 | AN15: =SUM(G15:J15) -> 35756 | AO15: 34478 | AP15: =+AP14*0.655 -> 36601.898 | AQ15: =+AQ14*0.6 -> 34393.204 | AR15: =+AR14*0.58 -> 34101.362 | AS15: =+AS14*0.56 -> 38605.338 | AT15: =+AT14*0.54 -> 40023.844 | AU15: =+AU14*0.52 -> 41432.346 | AV15: =+AV14*0.5 -> 42824.085 | AW15: =+AW14*0.5 -> 46032.458 | AX15: =+AX14*0.5 -> 49482.991 | AY15: =+AY14*0.5 -> 53196.529
B16: R&D | C16: 4109 | D16: 4080 | E16: 3870 | F16: 3987 | G16: 4382 | H16: 4239 | I16: 4049 | J16: 3876 | K16: 3640 | L16: 3684 | M16: 3231 | N16: =+AO16-SUM(K16:M16) -> 3219 | AD16: 11537 | AE16: 12128 | AF16: 12685 | AG16: 13035 | AH16: 13543 | AI16: 13362 | AJ16: 13556 | AK16: 15190 | AL16: 17528 | AM16: =SUM(C16:F16) -> 16046 | AN16: =SUM(G16:J16) -> 16546 | AO16: 13774 | AP16: =+AP14*0.26 -> 14528.998 | AQ16: =+AQ14*0.26 -> 14903.722 | AR16: =+AR14*0.26 -> 15286.817 | AS16: =+AS14*0.26 -> 17923.907 | AT16: =+AT14*0.26 -> 19270.74 | AU16: =+AU14*0.26 -> 20716.173 | AV16: =+AV14*0.26 -> 22268.524 | AW16: =+AW14*0.26 -> 23936.878 | ... AY16: =+AY14*0.26 -> 27662.195
B17: M,G&A | C17: 1303 | D17: 1374 | E17: 1340 | F17: 1617 | G17: 1556 | H17: 1329 | I17: 1383 | J17: 1239 | K17: 1177 | L17: 1144 | M17: 1129 | N17: =+AO17-SUM(K17:M17) -> 1174 | AD17: 8136 | AE17: 7930 | AF17: 8377 | AG17: 7452 | AH17: 6750 | AI17: 6350 | AJ17: 6180 | AK17: 6543 | AL17: 7002 | AM17: =SUM(C17:F17) -> 5634 | AN17: =SUM(G17:J17) -> 5507 | AO17: 4624 | AP17: =+AP14*0.08 -> 4470.4608 | AQ17: =+AQ14*0.08 -> 4585.7606 | AR17: =+AR14*0.08 -> 4703.6361 | AS17: =+AS14*0.08 -> 5515.0483 | AT17: =+AT14*0.08 -> 5929.4584 | AU17: =+AU14*0.08 -> 6374.207 | AV17: =+AV14*0.08 -> 6851.8537 | AW17: =+AW14*0.08 -> 7365.1933 | ... AY17: =+AY14*0.08 -> 8511.4446
B18: Op Income | C18: =+C14-SUM(C15:C17) -> -1404 | D18: =+D14-SUM(D15:D17) -> -816 | E18: =+E14-SUM(E15:E17) -> 808 | F18: =+F14-SUM(F15:F17) -> 1443 | G18: =+G14-SUM(G15:G17) -> -721 | H18: =+H14-SUM(H15:H17) -> -1021 | I18: =+I14-SUM(I15:I17) -> -3435 | J18: =+J14-SUM(J15:J17) -> 469 | ... M18: =+M14-SUM(M15:M17) -> 858 | N18: =+AO18-SUM(K18:M18) -> 550 | AD18: =+AD14-SUM(AD15:AD17) -> 15936 | AE18: =+AE14-SUM(AE15:AE17) -> 14621 | AF18: =+AF14-SUM(AF15:AF17) -> 15171 | AG18: =+AG14-SUM(AG15:AG17) -> 18611 | AH18: =+AH14-SUM(AH15:AH17) -> 23444 | AI18: =+AI14-SUM(AI15:AI17) -> 22428 | AJ18: =+AJ14-SUM(AJ15:AJ17) -> 23876 | AK18: =+AK14-SUM(AK15:AK17) -> 22757 | AL18: =+AL14-SUM(AL15:AL17) -> 2856 | AM18: =SUM(C18:F18) -> 31 | AN18: =SUM(G18:J18) -> -4708 | AO18: =+AO14-SUM(AO15:AO17) -> -23 | AP18: =+AP14-SUM(AP15:AP17) -> 279.4038 | AQ18: =+AQ14-SUM(AQ15:AQ17) -> 3439.3204 | AR18: =+AR14-SUM(AR15:AR17) -> 4703.6361 | AS18: =+AS14-SUM(AS15:AS17) -> 6893.8103 | AT18: =+AT14-SUM(AT15:AT17) -> 8894.1876 | AU18: =+AU14-SUM(AU15:AU17) -> 11154.862 | AV18: =+AV14-SUM(AV15:AV17) -> 13703.707 | ... AY18: =+AY14-SUM(AY15:AY17) -> 17022.889
B19: Equity Investments | C19: 169 | D19: -24 | E19: -191 | F19: 86 | G19: 205 | H19: -120 | I19: -159 | J19: 316 | K19: -112 | L19: 502 | M19: 221 | N19: =+AO19-SUM(K19:M19) -> -97 | AD19: 411 | AE19: 315 | AF19: 506 | AG19: 2651 | AH19: -125 | AI19: 1539 | AJ19: 1904 | AK19: 2729 | AL19: 4268 | AM19: =SUM(C19:F19) -> 40 | AN19: =SUM(G19:J19) -> 242 | AO19: 514 | AP19: =+AN19 -> 242 | AQ19: =+AP19 -> 242 | AR19: =+AQ19 -> 242 | AS19: =+AR19 -> 242 | AT19: =+AS19 -> 242 | AU19: =+AT19 -> 242 | AV19: =+AU19 -> 242 | AW19: =+AV19 -> 242 | AX19: =+AW19 -> 242 | AY19: =+AX19 -> 242
B20: Interest and other | C20: 141 | D20: 224 | E20: 147 | F20: 117 | G20: 145 | H20: 80 | I20: 130 | J20: -129 | K20: -173 | L20: -95 | M20: 3670 | N20: =+AO20-SUM(K20:M20) -> -145 | AD20: 43 | AE20: -105 | AF20: -703 | AG20: -349 | AH20: 126 | AI20: 484 | AJ20: -504 | AK20: -482 | AL20: 1166 | AM20: =SUM(C20:F20) -> 629 | AN20: =SUM(G20:J20) -> 226 | AO20: 3257 | AP20: =+AN20 -> 226 | AQ20: =+AP20 -> 226 | AR20: =+AQ20 -> 226 | AS20: =+AR20 -> 226 | AT20: =+AS20 -> 226 | AU20: =+AT20 -> 226 | AV20: =+AU20 -> 226 | AW20: =+AV20 -> 226 | AX20: =+AW20 -> 226 | AY20: =+AX20 -> 226
B21: EBT | C21: =SUM(C18:C20) -> -1094 | D21: =SUM(D18:D20) -> -616 | E21: =SUM(E18:E20) -> 764 | F21: =SUM(F18:F20) -> 1646 | G21: =SUM(G18:G20) -> -371 | H21: =SUM(H18:H20) -> -1061 | I21: =SUM(I18:I20) -> -3464 | J21: =SUM(J18:J20) -> 656 | ... M21: =SUM(M18:M20) -> 4749 | N21: =+AO21-SUM(K21:M21) -> 308 | AD21: =SUM(AD18:AD20) -> 16390 | AE21: =SUM(AE18:AE20) -> 14831 | AF21: =SUM(AF18:AF20) -> 14974 | AG21: =SUM(AG18:AG20) -> 20913 | AH21: =SUM(AH18:AH20) -> 23445 | AI21: =SUM(AI18:AI20) -> 24451 | AJ21: =SUM(AJ18:AJ20) -> 25276 | AK21: =SUM(AK18:AK20) -> 25004 | AL21: =SUM(AL18:AL20) -> 8290 | AM21: =SUM(C21:F21) -> 700 | AN21: =SUM(G21:J21) -> -4240 | AO21: =SUM(AO18:AO20) -> 3748 | AP21: =SUM(AP18:AP20) -> 747.4038 | AQ21: =SUM(AQ18:AQ20) -> 3907.3204 | AR21: =SUM(AR18:AR20) -> 5171.6361 | AS21: =SUM(AS18:AS20) -> 7361.8103 | AT21: =SUM(AT18:AT20) -> 9362.1876 | AU21: =SUM(AU18:AU20) -> 11622.862 | AV21: =SUM(AV18:AV20) -> 14171.707 | ... AY21: =SUM(AY18:AY20) -> 17490.889
B22: Taxes | C22: 1610 | D22: -2289 | E22: 7271 | F22: 128 | G22: -282 | H22: -350 | I22: 7903 | J22: 752 | K22: 301 | L22: 255 | M22: 304 | N22: =+AO22-SUM(K22:M22) -> 671 | AD22: 4097 | AE22: 2792 | AF22: 2620 | AG22: 10751 | AH22: 2264 | AI22: 3010 | AJ22: 4179 | AK22: 1835 | AL22: -249 | AM22: =SUM(C22:F22) -> 6720 | AN22: =SUM(G22:J22) -> 8023 | AO22: 1531 | AP22: =+AP21*0.21 -> 156.9548 | AQ22: =+AQ21*0.21 -> 820.53729 | AR22: =+AR21*0.21 -> 1086.0436 | AS22: =+AS21*0.21 -> 1545.9802 | AT22: =+AT21*0.21 -> 1966.0594 | AU22: =+AU21*0.21 -> 2440.8011 | AV22: =+AV21*0.21 -> 2976.0585 | AW22: =+AW21*0.21 -> 3191.6612 | ... AY22: =+AY21*0.21 -> 3673.0867
B23: Net Income | C23: =+C21-C22 -> -2704 | D23: =+D21-D22 -> 1673 | E23: =+E21-E22 -> -6507 | F23: =+F21-F22 -> 1518 | G23: =+G21-G22 -> -89 | H23: =+H21-H22 -> -711 | I23: =+I21-I22 -> -11367 | J23: =+J21-J22 -> -96 | ... M23: =+M21-M22 -> 4445 | N23: =+AO23-SUM(K23:M23) -> -363 | AD23: =+AD21-AD22 -> 12293 | AE23: =+AE21-AE22 -> 12039 | AF23: =+AF21-AF22 -> 12354 | AG23: =+AG21-AG22 -> 10162 | AH23: =+AH21-AH22 -> 21181 | AI23: =+AI21-AI22 -> 21441 | AJ23: =+AJ21-AJ22 -> 21097 | AK23: =+AK21-AK22 -> 23169 | AL23: =+AL21-AL22 -> 8539 | AM23: =SUM(C23:F23) -> -6020 | AN23: =SUM(G23:J23) -> -12263 | AO23: =+AO21-AO22 -> 2217 | AP23: =+AP21-AP22 -> 590.449 | AQ23: =+AQ21-AQ22 -> 3086.7831 | AR23: =+AR21-AR22 -> 4085.5925 | AS23: =+AS21-AS22 -> 5815.8302 | AT23: =+AT21-AT22 -> 7396.1282 | AU23: =+AU21-AU22 -> 9182.0612 | AV23: =+AV21-AV22 -> 11195.649 | ... AY23: =+AY21-AY22 -> 13817.802 | AZ23: =+AY23*(1+$BB$25) -> 13955.98 | BA23: =+AZ23*(1+$BB$25) -> 14095.54 | BB23: =+BA23*(1+$BB$25) -> 14236.496 | BC23: =+BB23*(1+$BB$25) -> 14378.861 | BD23: =+BC23*(1+$BB$25) -> 14522.649 | BE23: =+BD23*(1+$BB$25) -> 14667.876 | BF23: =+BE23*(1+$BB$25) -> 14814.554 | BG23: =+BF23*(1+$BB$25) -> 14962.7 | ... IQ23: =+IP23*(1+$BB$25) -> 101091.29
B25: Growth Analysis Y/Y | BA25: Terminal | BB25: 0.01
B26: CCG | G26: =+IFERROR(G5/C5-1,"") -> 0.43454136 | H26: =+IFERROR(H5/D5-1,"") -> 0.20103245 | I26: =+IFERROR(I5/E5-1,"") -> -0.068259819 | J26: =+IFERROR(J5/F5-1,"") -> -0.093509724 | K26: =+IFERROR(K5/G5-1,"") -> -0.077843588 | L26: =+IFERROR(L5/H5-1,"") -> -0.033402923 | M26: =+IFERROR(M5/I5-1,"") -> 0.16439291 | N26: =+IFERROR(N5/J5-1,"") -> 0.021953349 | ... R26: =+IFERROR(R5/N5-1,"") -> -1 | AK26: =+IFERROR((AK5/AJ5-1),"") -> 0.02521407 | AL26: =+IFERROR((AL5/AK5-1),"") -> -0.22789588 | AM26: =+IFERROR((AM5/AL5-1),"") -> -0.077267567 | AN26: =+IFERROR((AN5/AM5-1),"") -> 0.085617609 | AO26: =+IFERROR((AO5/AN5-1),"") -> 0.014639675 | AP26: =+IFERROR((AP5/AO5-1),"") -> 0.05 | AQ26: =+IFERROR((AQ5/AP5-1),"") -> 0.02 | AR26: =+IFERROR((AR5/AQ5-1),"") -> 0.02 | ... AY26: =+IFERROR((AY5/AX5-1),"") -> 0.04 | BA26: Discount | BB26: 0.07
B27: DCAI | G27: =+IFERROR(G6/C6-1,"") -> 0.31954498 | H27: =+IFERROR(H6/D6-1,"") -> 0.20602219 | I27: =+IFERROR(I6/E6-1,"") -> 0.088751625 | J27: =+IFERROR(J6/F6-1,"") -> -0.033114473 | K27: =+IFERROR(K6/G6-1,"") -> 0.07784744 | L27: =+IFERROR(L6/H6-1,"") -> 0.03521682 | M27: =+IFERROR(M6/I6-1,"") -> 0.22932219 | N27: =+IFERROR(N6/J6-1,"") -> 0.39858282 | ... R27: =+IFERROR(R6/N6-1,"") -> -1 | AK27: =+IFERROR((AK6/AJ6-1),"") -> -0.13071294 | AL27: =+IFERROR((AL6/AK6-1),"") -> -0.15402583 | AM27: =+IFERROR((AM6/AL6-1),"") -> -0.34178996 | AN27: =+IFERROR((AN6/AM6-1),"") -> 0.13723783 | AO27: =+IFERROR((AO6/AN6-1),"") -> 0.17746538 | AP27: =+IFERROR((AP6/AO6-1),"") -> 0.05 | AQ27: =+IFERROR((AQ6/AP6-1),"") -> 0.01 | AR27: =+IFERROR((AR6/AQ6-1),"") -> 0.01 | ... AY27: =+IFERROR((AY6/AX6-1),"") -> 0.05 | BA27: NPV | BB27: =NPV(BB26,AP23:IQ23) -> 168642.04
B28: Network/Edge | G28: =+IFERROR(G7/C7-1,"") -> -1 | H28: =+IFERROR(H7/D7-1,"") -> -1 | I28: =+IFERROR(I7/E7-1,"") -> 0.042068966 | J28: =+IFERROR(J7/F7-1,"") -> 0.10333107 | K28: =+IFERROR(K7/G7-1,"") | L28: =+IFERROR(L7/H7-1,"") | M28: =+IFERROR(M7/I7-1,"") -> -1 | N28: =+IFERROR(N7/J7-1,"") -> -1 | ... R28: =+IFERROR(R7/N7-1,"") | AK28: =+IFERROR((AK7/AJ7-1),"") | AL28: =+IFERROR((AL7/AK7-1),"") -> 0.11246239 | AM28: =+IFERROR((AM7/AL7-1),"") -> -0.34926181 | AN28: =+IFERROR((AN7/AM7-1),"") -> -0.45722203 | AO28: =+IFERROR((AO7/AN7-1),"") -> -1 | AP28: =+IFERROR((AP7/AO7-1),"") | AQ28: =+IFERROR((AQ7/AP7-1),"") | AR28: =+IFERROR((AR7/AQ7-1),"") | ... AY28: =+IFERROR((AY7/AX7-1),"") | BA28: Shares | BB28: =+Model!L5 -> 4995
B29: Total Intel Products | G29: =+IFERROR(G8/C8-1,"") -> 0.1913951 | H29: =+IFERROR(H8/D8-1,"") -> 0.057438711 | I29: =+IFERROR(I8/E8-1,"") -> -0.016380215 | J29: =+IFERROR(J8/F8-1,"") -> -0.057244174 | K29: =+IFERROR(K8/G8-1,"") -> -0.028592678 | L29: =+IFERROR(L8/H8-1,"") -> -0.01155005 | M29: =+IFERROR(M8/I8-1,"") -> 0.037899918 | N29: =+IFERROR(N8/J8-1,"") -> -0.0074460735 | ... R29: =+IFERROR(R8/N8-1,"") -> -1 | AK29: =+IFERROR((AK8/AJ8-1),"") | AL29: =+IFERROR((AL8/AK8-1),"") -> -0.16668525 | AM29: =+IFERROR((AM8/AL8-1),"") -> -0.20258628 | AN29: =+IFERROR((AN8/AM8-1),"") -> 0.03354522 | AO29: =+IFERROR((AO8/AN8-1),"") -> -0.0024154589 | AP29: =+IFERROR((AP8/AO8-1),"") -> 0.05 | AQ29: =+IFERROR((AQ8/AP8-1),"") -> 0.01655747 | AR29: =+IFERROR((AR8/AQ8-1),"") -> 0.016579677 | ... AY29: =+IFERROR((AY8/AX8-1),"") -> 0.043528155 | BA29: Estimate | BB29: =+BB27/BB28 -> 33.762171
B30: Intel Foundry | G30: =+IFERROR(G11/C11-1,"") -> -0.098323329 | H30: =+IFERROR(H11/D11-1,"") -> 0.026366251 | I30: =+IFERROR(I11/E11-1,"") -> -0.080304311 | J30: =+IFERROR(J11/F11-1,"") -> -0.13004831 | K30: =+IFERROR(K11/G11-1,"") -> 0.071395776 | L30: =+IFERROR(L11/H11-1,"") -> 0.031527324 | M30: =+IFERROR(M11/I11-1,"") -> -0.026884191 | N30: =+IFERROR(N11/J11-1,"") -> 0.0011106175 | ... R30: =+IFERROR(R11/N11-1,"") -> -1 | AK30: =+IFERROR((AK11/AJ11-1),"") | AL30: =+IFERROR((AL11/AK11-1),"") -> 0.13867684 | AM30: =+IFERROR((AM11/AL11-1),"") -> 20.128492 | AN30: =+IFERROR((AN11/AM11-1),"") -> -0.074986779 | AO30: =+IFERROR((AO11/AN11-1),"") -> 0.019094443 | AP30: =+IFERROR((AP11/AO11-1),"") -> 0.03 | AQ30: =+IFERROR((AQ11/AP11-1),"") -> 0.03 | AR30: =+IFERROR((AR11/AQ11-1),"") -> 0.03 | ... AY30: =+IFERROR((AY11/AX11-1),"") -> 0.1 | BA30: Current | BB30: =+Model!L4 -> 46.79
B31: All Other | G31: =+IFERROR(G12/C12-1,"") -> -0.55347222 | H31: =+IFERROR(H12/D12-1,"") -> -0.37914024 | I31: =+IFERROR(I12/E12-1,"") -> -0.28443526 | J31: =+IFERROR(J12/F12-1,"") -> -0.19660756 | K31: =+IFERROR(K12/G12-1,"") -> 0.46656299 | L31: =+IFERROR(L12/H12-1,"") -> 0.19523269 | M31: =+IFERROR(M12/I12-1,"") -> -0.04427334 | N31: =+IFERROR(N12/J12-1,"") -> -0.44913628 | ... R31: =+IFERROR(R12/N12-1,"") -> -1 | AK31: =+IFERROR((AK12/AJ12-1),"") | AL31: =+IFERROR((AL12/AK12-1),"") -> -0.9609484 | AM31: =+IFERROR((AM12/AL12-1),"") -> 27.612245 | AN31: =+IFERROR((AN12/AM12-1),"") -> -0.35716833 | AO31: =+IFERROR((AO12/AN12-1),"") -> -0.011650485 | AP31: =+IFERROR((AP12/AO12-1),"") -> 0.01 | AQ31: =+IFERROR((AQ12/AP12-1),"") -> 0.01 | AR31: =+IFERROR((AR12/AQ12-1),"") -> 0.01 | ... AY31: =+IFERROR((AY12/AX12-1),"") -> 0.01 | BB31: =+BB29/BB30-1 -> -0.27843191
B32: Interseg Elim | G32: =+IFERROR(G13/C13-1,"") -> -0.07150435 | H32: =+IFERROR(H13/D13-1,"") -> 0.085511292 | I32: =+IFERROR(I13/E13-1,"") -> -0.027608056 | J32: =+IFERROR(J13/F13-1,"") -> -0.11732187 | K32: =+IFERROR(K13/G13-1,"") -> 0.073583181 | L32: =+IFERROR(L13/H13-1,"") -> 0.033426835 | M32: =+IFERROR(M13/I13-1,"") -> -0.016290435 | N32: =+IFERROR(N13/J13-1,"") -> 0.0060310833 | ... R32: =+IFERROR(R13/N13-1,"") -> -1 | AK32: =+IFERROR((AK13/AJ13-1),"") | AL32: =+IFERROR((AL13/AK13-1),"") | AM32: =+IFERROR((AM13/AL13-1),"") | AN32: =+IFERROR((AN13/AM13-1),"") -> -0.03870357 | AO32: =+IFERROR((AO13/AN13-1),"") -> 0.024388831 | AP32: =+IFERROR((AP13/AO13-1),"") -> 0 | AQ32: =+IFERROR((AQ13/AP13-1),"") -> 0 | AR32: =+IFERROR((AR13/AQ13-1),"") -> 0 | ... AY32: =+IFERROR((AY13/AX13-1),"") -> 0
B33: Revenue | G33: =+IFERROR(G14/C14-1,"") -> 0.086128895 | H33: =+IFERROR(H14/D14-1,"") -> -0.0089582207 | I33: =+IFERROR(I14/E14-1,"") -> -0.061731883 | J33: =+IFERROR(J14/F14-1,"") -> -0.074386603 | K33: =+IFERROR(K14/G14-1,"") -> -0.0044797234 | L33: =+IFERROR(L14/H14-1,"") -> 0.0020260267 | M33: =+IFERROR(M14/I14-1,"") -> 0.027777778 | N33: =+IFERROR(N14/J14-1,"") -> -0.041093969 | ... R33: =+IFERROR(R14/N14-1,"") -> -1 | AA33: =+IFERROR((AA14/Z14-1),"") -> 0.23785618 | AB33: =+IFERROR((AB14/AA14-1),"") -> -0.012185411 | AC33: =+IFERROR((AC14/AB14-1),"") -> -0.011867044 | AD33: =+IFERROR((AD14/AC14-1),"") -> 0.059990893 | AE33: =+IFERROR((AE14/AD14-1),"") -> -0.0092178271 | AF33: =+IFERROR((AF14/AE14-1),"") -> 0.072838949 | AG33: =+IFERROR((AG14/AF14-1),"") -> 0.056813781 | AH33: =+IFERROR((AH14/AG14-1),"") -> 0.12885391 | ... AY33: =+IFERROR((AY14/AX14-1),"") -> 0.075046753
B35: GM% | C35: =IFERROR((C14-C15)/C14,"") -> 0.34212548 | D35: =IFERROR((D14-D15)/D14,"") -> 0.35817438 | E35: =IFERROR((E14-E15)/E14,"") -> 0.42506004 | F35: =IFERROR((F14-F15)/F14,"") -> 0.45741919 | G35: =IFERROR((G14-G15)/G14,"") -> 0.41001257 | H35: =IFERROR((H14-H15)/H14,"") -> 0.35432089 | I35: =IFERROR((I14-I15)/I14,"") -> 0.15033123 | J35: =IFERROR((J14-J15)/J14,"") -> 0.39158485 | ... N35: =IFERROR((N14-N15)/N14,"") -> 0.36148896 | X35: =IFERROR((X14-X15)/X14,"") -> 0.55456819 | Y35: =IFERROR((Y14-Y15)/Y14,"") -> 0.55686509 | Z35: =IFERROR((Z14-Z15)/Z14,"") -> 0.65311877 | AA35: =IFERROR((AA14-AA15)/AA14,"") -> 0.62514121 | AB35: =IFERROR((AB14-AB15)/AB14,"") -> 0.62149191 | AC35: =IFERROR((AC14-AC15)/AC14,"") -> 0.59803066 | AD35: =IFERROR((AD14-AD15)/AD14,"") -> 0.63735457 | AE35: =IFERROR((AE14-AE15)/AE14,"") -> 0.62648361 | ... AY35: =IFERROR((AY14-AY15)/AY14,"") -> 0.5
B36: OM% | C36: =+IFERROR((C18/C14),"") -> -0.11984635 | D36: =+IFERROR((D18/D14),"") -> -0.063016449 | E36: =+IFERROR((E18/E14),"") -> 0.057070208 | F36: =+IFERROR((F18/F14),"") -> 0.093664806 | G36: =+IFERROR((G18/G14),"") -> -0.056664571 | H36: =+IFERROR((H18/H14),"") -> -0.079560508 | I36: =+IFERROR((I18/I14),"") -> -0.25858175 | J36: =+IFERROR((J18/J14),"") -> 0.032889201 | ... N36: =+IFERROR((N18/N14),"") -> 0.04022232 | AD36: =+IFERROR((AD18/AD14),"") -> 0.28523358 | AE36: =+IFERROR((AE18/AE14),"") -> 0.26413151 | AF36: =+IFERROR((AF18/AF14),"") -> 0.25545995 | AG36: =+IFERROR((AG18/AG14),"") -> 0.29653766 | AH36: =+IFERROR((AH18/AH14),"") -> 0.3309056 | AI36: =+IFERROR((AI18/AI14),"") -> 0.3116515 | AJ36: =+IFERROR((AJ18/AJ14),"") -> 0.3066254 | AK36: =+IFERROR((AK18/AK14),"") -> 0.28553683 | ... AY36: =+IFERROR((AY18/AY14),"") -> 0.16
B38: % Of Revenue
B39: CoS | AD39: =+AD15/AD14 -> 0.36264543 | AE39: =+AE15/AE14 -> 0.37351639 | AF39: =+AF15/AF14 -> 0.38988331 | AG39: =+AG15/AG14 -> 0.37703351 | AH39: =+AH15/AH14 -> 0.3826643 | AI39: =+AI15/AI14 -> 0.41443757 | AJ39: =+AJ15/AJ14 -> 0.43991678 | AK39: =+AK15/AK14 -> 0.44177468 | ... AY39: =+AY15/AY14 -> 0.5
B40: R&D | C40: =+C16/C$14 -> 0.35074691 | D40: =+D16/D$14 -> 0.31508225 | E40: =+E16/E$14 -> 0.27334369 | F40: =+F16/F$14 -> 0.25879527 | G40: =+G16/G$14 -> 0.34438856 | H40: =+H16/H$14 -> 0.33032027 | I40: =+I16/I$14 -> 0.30480277 | J40: =+J16/J$14 -> 0.27180926 | ... N40: =+N16/N$14 -> 0.23541027 | AD40: =+AD16/AD$14 -> 0.20649723 | AE40: =+AE16/AE$14 -> 0.21909493 | AF40: =+AF16/AF$14 -> 0.21359894 | AG40: =+AG16/AG$14 -> 0.20769268 | AH40: =+AH16/AH$14 -> 0.19115571 | AI40: =+AI16/AI$14 -> 0.18567359 | AJ40: =+AJ16/AJ$14 -> 0.17409172 | AK40: =+AK16/AK$14 -> 0.1905921 | ... AY40: =+AY16/AY$14 -> 0.26
B41: M,G&A | C41: =+C17/C$14 -> 0.11122493 | D41: =+D17/D$14 -> 0.10610858 | E41: =+E17/E$14 -> 0.094646136 | F41: =+F17/F$14 -> 0.10495911 | G41: =+G17/G$14 -> 0.12228859 | H41: =+H17/H$14 -> 0.10356113 | I41: =+I17/I$14 -> 0.10411021 | J41: =+J17/J$14 -> 0.086886396 | ... N41: =+N17/N$14 -> 0.08585637 | AD41: =+AD17/AD$14 -> 0.14562377 | AE41: =+AE17/AE$14 -> 0.14325716 | AF41: =+AF17/AF$14 -> 0.14105781 | AG41: =+AG17/AG$14 -> 0.11873616 | AH41: =+AH17/AH$14 -> 0.09527439 | AI41: =+AI17/AI$14 -> 0.088237338 | AJ41: =+AJ17/AJ$14 -> 0.079366099 | AK41: =+AK17/AK$14 -> 0.082096388 | ... AY41: =+AY17/AY$14 -> 0.08
B44: Cash | C44: 8232 | D44: 8349 | E44: 7621 | F44: 7079 | G44: 6923 | H44: 11287 | I44: 8785 | J44: 8249 | K44: 8947 | L44: 9643 | M44: 11141 | N44: 14265
B45: Investments | C45: 19302 | D45: 15908 | E45: 17409 | F45: 17955 | G45: 14388 | H45: 17986 | I45: 15301 | J45: 13813 | K45: 12101 | L45: 11563 | M45: 19794 | N45: 23151
...

Sheet Model
B2: CEO | C2: Lip-BU Tan
B3: CFO | C3: David Zinsner
B4: Founded | C4: 1968; Mountain View, CA | K4: P | L4: 46.79
K5: S | L5: 4995 | M5: Q425
K6: MC | L6: =+L4*L5 -> 233716.05
K7: C | L7: =14265+23151 -> 37416 | M7: =+M5 -> Q425
K8: D | L8: =2499+44086 -> 46585 | M8: =+M7 -> Q425
K9: EV | L9: =+L6-L7+L8 -> 242885.05
C11: 2.17.26 Notes
C12: company is supply constrained. 6m ago customers said they wanted similar units with higher cores, not they want higher vol and higher cores which intc can't match today.
C13: current plan is feeding cpu to keep OEM customers happy then allocating incremental capacity to DCAI
C14: focus is to improve yields
B19: Products | L19: Press | M19: Contains | Q19: Earnings Calls
B20: products | C20: manufactured | D20: about | L20: 45622 | M20: $7.86B funding award under CHIPS Act | Q20: Q425
B21: intel 4 | C21: Ireland | D21: 1st ever EUV Lithography, 20% performance over intel 7 | L21: 45612 | M21: foundry oeprating as separate entity | Q21: Q325
B22: intel 3 | C22: Oregon/Ireland | D22: 18% performance over intel 4 | L22: 45671 | M22: icap to become stand alone investment fund
B23: intel 18A | D23: Pantehr Lake, starting 2025 | L23: 45631 | M23: appoints Eric Meurice and Steve Sanghi to BoD
B24: intel 7 | C24: AZ & Israel | D24: 13th and 14th gen intel core | L24: 45628 | M24: ceo Pat Gelsinger fired..basically
B25: intel 14A | D25: in development | L25: 45939 | M25: Panther Lake Architecture built on 18A
L26: 46027
B27: intel 7 | C27: 2021-2023 | D27: already in high volproduction
B28: intel 4 | C28: 2023-2024 | D28: strong volume production now
B29: intel 3 | C29: 2024 | D29: ramp up in 2024
B30: intl 20A | C30: 2024 | D30: canceled, replace with intel 18A
B31: intel 18A | C31: 2025 | D31: most important node, make or break
B32: intel 14A | C32: 2028-2029
B34: 2014-2019 | C34: 10nm issues
C35: planned for 2016, delayed until 2019 due to yield issues
C36: tsmc took over, amd caught up
B37: 2020 | C37: intel admits 7nm (intel 4) is delayed
C38: originally meant for 2021, but pushed to 2023
C39: ceo Bob Swan fired in 2021, Pat brought in to fix the problem
B40: 2022 | C40: intel's "five nodes in Four Years"plan announced
C41: promised
C42: intel 7 2022 (delivered but late)
C43: intel 4 (2023-2025) in high volume now
C44: intel 3 (2024) in progress
C45: intel 20A (2024) cancelled --> intel 18A now the focus
C46: intel 18A (2025) no high vol proof yet
B51: "Some of our most advanced current and future products are or will be either exclusively manufactured by TSMC or reliant upon critical components, including various compute die, manufactured by TSMC."
