Workbook

Sheet Main
B2: Founded | C2: 1988
G3: P | H3: 6.84
G4: S | H4: 17.090253 | I4: Q325
G5: MC | H5: =+H3*H4 -> 116.89733
G6: C | H6: 17.343 | I6: =+I4 -> Q325
G7: D | H7: =15+1.234 -> 16.234 | I7: =+I6 -> Q325
B8: Embedded FPGA (eFGPA) IP | G8: EV | H8: =+H5-H6+H7 -> 115.78833
B10: Field Programmable Gate Array: semiconductor that conisst of programmable logic blocks and interconnects that can be reconfigured after manufacturing. Allows for customization
B11: reconfigurable chip that allows users to modify the logic after manufacturing
B14: System on Chip (SoC): integrated semiconductor containing multiple components. processor, memory input/output interfaces, and hardware accelerators
B15: designed to execute pre-defined tasks efficiently by integrating everything needed onto a single chip
B16: optimized for specific applications, like smartphones, wearables, IoT devices, and AI processing
B17: cannot be reprogrammed after manufacturing
B18: Use Cases
B19: smartphones
B20: AI powered voice assistants
B21: Industrial automation | D21: 0
B24: Traditional FPGA
B25: Placement: Motherboard or Pcle Card: the fgpa sits as a standalone chip on a circuit board
B26: Adjacent to CPU/GPU: typically connected via Pcle, memory buses, or high speed interconnects
B28: fpga's act as accelerators for specific tasks, offloading computational work for the CPU or GPU
B30: Embedded FPGA
B31: eFPGA is not a sperate chip. Is is integrated inside another chip, such as an AISC or SoC
B32: Placement: Inside a custom ASIC or SoC, instead fo sitting next to the CPU or GPU, the eFPGA logic is embdedded inside a large semiconductor device
B39: EOS S3 SOC | C39: designed for AI/ML, voice processing, and ulta low power IoT apps
B40: ARTICLINK III SoC | C40: used for sensor fusion in wearables, industrial IoT, and smart devices

Sheet Model
C2: Q123 | D2: Q223 | E2: Q323 | F2: Q423 | G2: Q124 | H2: Q224 | I2: Q324 | J2: Q424 | K2: Q125 | L2: Q225 | M2: Q325 | N2: Q425 | R2: 2021 | S2: 2022 | T2: 2023 | U2: 2024
B3: New products | G3: 4538 | I3: 3537 | K3: 3748 | L3: 2918 | M3: 1100 | N3: =+L3*3 -> 8754
B4: Mature Products | G4: 1131 | I4: 736 | K4: 578 | L4: 769 | M4: =+M5-M3 -> 929
B5: R | C5: 4133 | D5: 2921 | E5: 6665 | F5: =+T5-SUM(C5:E5) -> 7479 | G5: 5669 | H5: 4127 | I5: =SUM(I3:I4) -> 4273 | J5: =+U5-SUM(G5:I5) -> 6043 | K5: 4325 | L5: 3687 | M5: 2029 | N5: 6000 | R5: 12685 | S5: 16180 | T5: 21198 | U5: 20112 | V5: =SUM(K5:N5) -> 16041
B6: C | C6: 1743 | D6: 1718 | E6: 1537 | F6: =+T6-SUM(C6:E6) -> 1713 | G6: 1321 | H6: 2022 | I6: 1888 | J6: =+U6-SUM(G6:I6) -> 2995 | K6: 2448 | L6: 2733 | R6: 5266 | S6: 7378 | T6: 6711 | U6: 8226
B7: R&D | C7: 1629 | D7: 1505 | E7: 1933 | F7: =+T7-SUM(C7:E7) -> 1381 | G7: 2351 | H7: 1527 | I7: 1954 | J7: =+U7-SUM(G7:I7) -> 712 | K7: 1268 | L7: 1193 | R7: 6927 | S7: 5001 | T7: 6448 | U7: 6544
B8: SG&A | C8: 1861 | D8: 1924 | E8: 1915 | F8: =+T8-SUM(C8:E8) -> 2269 | G8: 2095 | H8: 2095 | I8: 2292 | J8: =+U8-SUM(G8:I8) -> 2291 | K8: 2536 | L8: 1962 | R8: 8008 | S8: 7601 | T8: 7969 | U8: 8773
B9: Operating Income | C9: =+C5-SUM(C6:C8) -> -1100 | D9: =+D5-SUM(D6:D8) -> -2226 | E9: =+E5-SUM(E6:E8) -> 1280 | F9: =+T9-SUM(C9:E9) -> 2116 | G9: =+G5-SUM(G6:G8) -> -98 | H9: =+H5-SUM(H6:H8) -> -1517 | I9: =+I5-SUM(I6:I8) -> -1861 | J9: =+U9-SUM(G9:I9) -> 45 | K9: =+K5-SUM(K6:K8) -> -1927 | L9: =+L5-SUM(L6:L8) -> -2201 | R9: =+R5-SUM(R6:R8) -> -7516 | S9: =+S5-SUM(S6:S8) -> -3800 | T9: =+T5-SUM(T6:T8) -> 70 | U9: =+U5-SUM(U6:U8) -> -3431
B10: Interest Expense | C10: -58 | D10: -50 | E10: -48 | F10: =+T10-SUM(C10:E10) -> -59 | G10: -69 | H10: -40 | I10: -186 | J10: =+U10-SUM(G10:I10) -> -111 | K10: -97 | L10: -108 | R10: -130 | S10: -148 | T10: -215 | U10: -406
B11: Interest Income | C11: -63 | D11: 0 | E11: -36 | F11: =+T11-SUM(C11:E11) -> -17 | G11: 17 | H11: 1 | I11: -34 | J11: =+U11-SUM(G11:I11) -> 15 | K11: -7 | L11: -30 | R11: -43 | S11: -221 | T11: -116 | U11: -1
B12: EBT | C12: =+SUM(C9:C11) -> -1221 | D12: =+SUM(D9:D11) -> -2276 | E12: =+SUM(E9:E11) -> 1196 | F12: =+T12-SUM(C12:E12) -> 2040 | G12: =+SUM(G9:G11) -> -150 | H12: =+SUM(H9:H11) -> -1556 | I12: =+SUM(I9:I11) -> -2081 | J12: =+U12-SUM(G12:I12) -> -51 | K12: =+SUM(K9:K11) -> -2031 | L12: =+SUM(L9:L11) -> -2339 | R12: =+SUM(R9:R11) -> -7689 | S12: =+SUM(S9:S11) -> -4169 | T12: =+SUM(T9:T11) -> -261 | U12: =+SUM(U9:U11) -> -3838
B13: Taxes | C13: 7 | D13: -7 | E13: 4 | F13: =+T13-SUM(C13:E13) -> -2 | G13: 7 | H13: -6 | I13: 13 | J13: =+U13-SUM(G13:I13) -> -11 | K13: 5 | L13: 1 | R13: 119 | S13: 98 | T13: 2 | U13: 3
B14: Net Income | C14: =+C12-C13 -> -1228 | D14: =+D12-D13 -> -2269 | E14: =+E12-E13 -> 1192 | F14: =+T14-SUM(C14:E14) -> 2042 | G14: =+G12-G13 -> -157 | H14: =+H12-H13 -> -1550 | I14: =+I12-I13 -> -2094 | J14: =+U14-SUM(G14:I14) -> -40 | K14: =+K12-K13 -> -2036 | L14: =+L12-L13 -> -2340 | R14: =+R12-R13 -> -7808 | S14: =+S12-S13 -> -4267 | T14: =+T12-T13 -> -263 | U14: =+U12-U13 -> -3841
B15: Diluted | R15: 11535 | S15: 12588 | T15: 13453 | U15: 14510
B16: EPS | R16: =+R14/R15 -> -0.6768964 | S16: =+S14/S15 -> -0.33897363 | T16: =+T14/T15 -> -0.019549543 | U16: =+U14/U15 -> -0.26471399
B19: R Y/Y | G19: =+G5/C5-1 -> 0.37164287 | H19: =+H5/D5-1 -> 0.4128723 | I19: =+I5/E5-1 -> -0.35888972 | J19: =+J5/F5-1 -> -0.19200428 | K19: =+K5/G5-1 -> -0.23707885 | L19: =+L5/H5-1 -> -0.10661497 | S19: =+S5/R5-1 -> 0.27552227 | T19: =+T5/S5-1 -> 0.31013597 | U19: =+U5/T5-1 -> -0.051231248
B20: GM % | C20: =(C5-C6) / C5 -> 0.57827244 | D20: =(D5-D6) / D5 -> 0.41184526 | E20: =(E5-E6) / E5 -> 0.76939235 | F20: =(F5-F6) / F5 -> 0.77095868 | G20: =(G5-G6) / G5 -> 0.7669783 | H20: =(H5-H6) / H5 -> 0.51005573 | I20: =(I5-I6) / I5 -> 0.55815586 | J20: =(J5-J6) / J5 -> 0.50438524 | ... L20: =(L5-L6) / L5 -> 0.25874695 | R20: =(R5-R6) / R5 -> 0.58486401 | S20: =(S5-S6) / S5 -> 0.54400494 | T20: =(T5-T6) / T5 -> 0.68341353
U22: EV | V22: =+Main!H8 -> 115.78833
B23: Net Cash | F23: =+F24-F40-F44-F47 -> 3199 | I23: =+I24-I40-I44-I47 -> -748 | V23: =+$V$22/(20.112) -> 5.7571763
B24: Cash | F24: 24606 | I24: 22364 | J24: 21859 | L24: 19191 | U24: Implied | V24: =(SUM(K5:N5)*V23)/10^3 -> 92.350866
B25: A/R | F25: 1625 | I25: 657 | U25: Cash | V25: =+Main!H6 -> 17.343
B26: Contract assets | F26: 3609 | I26: 2331 | U26: Debt | V26: =+Main!H7 -> 16.234
B27: Note Recievable | F27: 1200 | U27: MC | V27: =+V24+V25-V26 -> 93.459866
B28: Inventories | F28: 2029 | I28: 1780 | U28: Shares | V28: =+Main!H4 -> 17.090253
B29: Prepaid Exp | F29: 1561 | I29: 2919 | U29: Price | V29: =+V27/V28 -> 5.4686063
B30: PPE | F30: 8948 | I30: 14137 | U30: Updie | V30: =+V29/V33-1 -> -0.20049615
B31: Capitalized software | F31: 2069 | I31: 2352
B32: Right of use | F32: 981 | I32: 828
B33: Intangibles | F33: 537 | I33: 457 | U33: current | V33: =+Main!H3 -> 6.84
B34: Non marketable equity | F34: 300 | I34: 300
B35: Goodwill | F35: 185 | I35: 185
B36: Note recievable | F36: 0 | I36: 1260
B37: Other Assets | F37: 142 | I37: 143
B38: Total Assets | F38: =+SUM(F24:F37) -> 47792 | I38: =+SUM(I24:I37) -> 49713
B40: Revolving Crediy | F40: 20000 | I40: 20000
B41: Trade payables | F41: 4657 | I41: 2877
B42: Accrued liabilities | F42: 2673 | I42: 1457
B43: Deferred revenue | F43: 1052 | I43: 449
B44: Note payable | F44: 946 | I44: 1798
B45: Lease Liabilities | F45: 302 | I45: 275
...
